File: addenda_25-06-02.dat
[Header]
TITLE,addenda_25-06-02.dat
BYAPP,HeatCapacity,3.9.11,1.7
INFO,,MASS:Sample Mass (mg)
INFO,,MASSERR:Sample Mass Error (mg)
INFO,,MOLWGHT:Formula Weight (g/mole)
INFO,,ATOMS:Atoms per Formula Unit
INFO,PPMS Heat Capacity Option 3.9.11 Build 2,APPNAME
DATATYPE,TIME,1
DATATYPE,COMMENT,2
STARTUPAXIS, X, 8, LINEAR, AUTO
STARTUPAXIS, Y1, 12, LINEAR, AUTO
[Data]
Time Stamp (Seconds),Comment (),System Status (Code),Puck Temp (Kelvin),System Temp (Kelvin),Field (Oersted),Pressure (Torr),Sample Temp (Kelvin),Temp Rise (Kelvin),Samp HC (µJ/K),Samp HC Err (µJ/K),Addenda HC (µJ/K),Addenda HC Err (µJ/K),Total HC (µJ/K),Total HC Err (µJ/K),Fit Deviation (ChiSquare),Time Const tau1 (seconds),Time Const tau2 (seconds),Sample Coupling (Percent),Debye Temp (Kelvin),Debye Temp Err (Kelvin),Cal Correction (Factor),Therm Resist (Ohms),Htr Resist (Ohms),Puck Resist (Ohms),Wire Cond (W/K),Meas Time (seconds),Temp Squared (K^2),Samp HC/Temp (µJ/K/K),Addenda Offset HC (µJ/K)
20599544.67,CALFILE: C:\QdPpms\HEATCA~1\TempCal\Standard\Puck1218.cal
20599544.88,,5905,2.00174,1.9923,0.588,9.3E-6,1.9760065,0.020952621,,0,0.18901253,0.001515,0.18901253,0.001515,30.203156,0.11806737,,,,,1,,,,1.600887E-6,0.23085465,3.9046015,,0
20599895.83,,5905,2.25907,2.2539,0.588,9.3E-6,2.2286471,0.020733319,,0,0.26325884,0.001354,0.26325884,0.001354,10.661551,0.12817318,,,,,1,,,,2.0539308E-6,0.23613475,4.9668679,,0
20600221.13,,5905,2.55072,2.5445,0.588,9.3E-6,2.516726,0.021601465,,0,0.36375816,0.001684,0.36375816,0.001684,33.935317,0.15269577,,,,,1,,,,2.3822412E-6,0.25634636,6.3339098,,0
20600560.48,,5905,2.87921,2.8752,0.588,9.3E-6,2.8379266,0.024038749,,0,0.50615177,0.002147,0.50615177,0.002147,13.837744,0.18637201,,,,,1,,,,2.7158143E-6,0.30539155,8.0538273,,0
20600909.83,,5905,3.24983,3.2478,0.588,9.3E-6,3.2009548,0.026925341,,0,0.71248146,0.002918,0.71248146,0.002918,5.4808769,0.22812491,,,,,1,,,,3.1232076E-6,0.37274402,10.246111,,0
20601545.52,,5905,3.6655,3.6648,0.588,9.4E-6,3.6108012,0.030095509,,0,1.0118859,0.003776,1.0118859,0.003776,15.160387,0.27931978,,,,,1,,,,3.6226791E-6,0.45624982,13.037885,,0
20602048.58,,5905,4.14392,4.144,0.588,9.3E-6,4.0832018,0.033909589,,0,1.4344785,0.003399,1.4344785,0.003399,3.317922,0.3553361,,,,,1,,,,4.0369625E-6,0.55863956,16.672537,,0
20602446.72,,5905,4.67421,4.6922,0.588,9.3E-6,4.6063149,0.039130543,,0,2.0534544,0.007837,2.0534544,0.007837,3.616282,0.42270155,,,,,1,,,,4.8579297E-6,0.71067221,21.218137,,0
20602676.34,,5905,5.26888,5.2859,0.588,9.4E-6,5.1922093,0.043549387,,0,2.8580595,0.01033,2.8580595,0.01033,3.0577881,0.50431502,,,,,1,,,,5.6672108E-6,0.84540309,26.959038,,0
20602912.41,,5905,5.94833,5.9683,0.588,9.4E-6,5.8601401,0.04878633,,0,4.0087086,0.01592,4.0087086,0.01592,3.7872527,0.60525382,,,,,1,,,,6.6231859E-6,1.00863,34.341242,,0
20603155.03,,5905,6.71568,6.7338,0.588,9.4E-6,6.6172025,0.054957256,,0,5.5583126,0.02259,5.5583126,0.02259,9.7350284,0.71116871,,,,,1,,,,7.815744E-6,1.2105076,43.787369,,0
20603402.41,,5905,7.58069,7.6025,0.588,9.4E-6,7.4694786,0.061411291,,0,7.6666814,0.03716,7.6666814,0.03716,8.0750585,0.83234916,,,,,1,,,,9.2108959E-6,1.4223374,55.793111,,0
20603656.69,,5905,8.55859,8.5798,0.588,9.3E-6,8.4304887,0.071966829,,0,10.426051,0.03159,10.426051,0.03159,4.8796522,0.98832164,,,,,1,,,,1.0549249E-5,1.6646983,71.07314,,0
20603919.39,,5905,9.66035,9.6845,0.588,9.4E-6,9.5152788,0.081340023,,0,14.134233,0.05133,14.134233,0.05133,5.1443705,1.1496203,,,,,1,,,,1.2294697E-5,1.9766433,90.54053,,0
20604187.17,,5905,10.9048,10.931,0.588,9.4E-6,10.74104,0.091686264,,0,18.944343,0.0771,18.944343,0.0771,6.7698943,1.318288,,,,,1,,,,1.4370413E-5,2.2992407,115.36995,,0
20604466.8,,5905,12.3115,12.3392,0.588,9.4E-6,12.130424,0.10583883,,0,25.332157,0.08092,25.332157,0.08092,16.060296,1.5413529,,,,,1,,,,1.6435014E-5,2.6365761,147.14718,,0
20604753.59,,5905,13.8957,13.9277,0.588,9.4E-6,13.695748,0.11950811,,0,33.737004,0.1186,33.737004,0.1186,15.770308,1.7715419,,,,,1,,,,1.9043864E-5,3.0827058,187.5735,,0
20605051.41,,5905,15.6887,15.7176,0.588,9.4E-6,15.463343,0.13401373,,0,44.637542,0.1835,44.637542,0.1835,23.993807,2.0405647,,,,,1,,,,2.1875092E-5,3.5430839,239.11496,,0
20605357.17,,5905,17.7095,17.7419,0.588,9.4E-6,17.463867,0.15351248,,0,58.651574,0.2141,58.651574,0.2141,22.129595,2.37035,,,,,1,,,,2.4743845E-5,4.0811294,304.98664,,0
20605676.84,,5905,19.9943,20.0265,0.588,9.3E-6,19.721965,0.17632525,,0,76.315704,0.258,76.315704,0.258,6.2556046,2.7619567,,,,,1,,,,2.7631028E-5,4.7407001,388.95591,,0
20606112.95,,5905,24.9967,25.0298,0.588,9.4E-6,24.701015,0.26199627,,0,121.74184,0.3654,121.74184,0.3654,4.2126056,3.6376818,,,,,1,,,,3.3466873E-5,8.1095363,610.14014,,0
20606516.3,,5905,29.9967,30.0355,0.588,9.4E-6,29.636217,0.25823155,,0,174.51674,0.7267,174.51674,0.7267,14.204596,4.4368049,,,,,1,,,,3.9333877E-5,7.2753636,878.30537,,0
20606926.23,,5905,34.9944,35.044,0.588,9.4E-6,34.609865,0.30162479,,0,235.21903,1.024,235.21903,1.024,6.8600487,5.3308546,,,,,1,,,,4.4124075E-5,8.8736099,1197.8427,,0
20607341.28,,5905,39.9936,40.0563,0.588,9.4E-6,39.571022,0.3525759,,0,302.06777,1.184,302.06777,1.184,12.441142,6.2956581,,,,,1,,,,4.7980333E-5,10.661709,1565.8657,,0
20607765.39,,5905,44.9949,45.0654,0.588,9.4E-6,44.543781,0.40092062,,0,378.16959,1.334,378.16959,1.334,7.9300539,7.3283023,,,,,1,,,,5.1603983E-5,12.591316,1984.1484,,0
20608191.39,,5905,49.9917,50.0802,0.588,9.3E-6,49.510093,0.44936652,,0,462.00291,1.486,462.00291,1.486,3.3731982,8.415271,,,,,1,,,,5.4900539E-5,14.656605,2451.2493,,0
20608627.2,,5905,54.9905,55.0899,0.588,9.4E-6,54.496667,0.49683208,,0,557.31478,1.574,557.31478,1.574,2.0375198,9.6249907,,,,,1,,,,5.790289E-5,16.830542,2969.8867,,0
20609068.27,,5905,59.9908,60.0954,0.588,9.3E-6,59.470408,0.54545182,,0,664.56218,1.789,664.56218,1.789,1.3400256,10.939806,,,,,1,,,,6.0747164E-5,19.249981,3536.7295,,0
20609519.36,,5905,64.9939,65.1194,0.588,9.1E-6,64.448476,0.59661942,,0,781.98163,1.914,781.98163,1.914,0.66378449,12.31987,,,,,1,,,,6.3473205E-5,21.879612,4153.606,,0
20609979.47,,5905,69.9882,70.1272,0.588,9.4E-6,69.426424,0.64748341,,0,908.57865,1.989,908.57865,1.989,0.48239921,13.729916,,,,,1,,,,6.6175106E-5,24.63974,4820.0283,,0
20610448.92,,5905,74.9894,75.1266,0.588,9.4E-6,74.421655,0.69729784,,0,1042.9532,2.086,1042.9532,2.086,0.26622867,15.168715,,,,,1,,,,6.8756861E-5,27.459832,5538.5827,,0
20610927.97,,5905,80.0011,80.0892,0.588,9.3E-6,79.40272,0.74633443,,0,1187.9396,2.058,1187.9396,2.058,0.25738791,16.627799,,,,,1,,,,7.1442986E-5,30.33743,6304.792,,0
20611423.8,,5905,85.0163,85.0174,0.588,9.4E-6,84.380473,0.79452884,,0,1341.0344,1.912,1341.0344,1.912,0.39726874,17.969769,,,,,1,,,,7.4627249E-5,33.255597,7120.0642,,0
20611927.31,,5905,90.0309,89.9133,0.588,9.3E-6,89.33329,0.83980689,,0,1503.6245,1.648,1503.6245,1.648,1.2030638,19.314074,,,,,1,,,,7.7851233E-5,35.939538,7980.4368,,0
20612440.72,,5905,95.0475,94.8203,0.588,9.3E-6,94.307242,0.88503419,,0,1680.2755,1.464,1680.2755,1.464,5.321186,20.648874,,,,,1,,,,8.1373711E-5,38.628149,8893.8559,,0
20612964.22,,5905,100.046,99.7406,0.588,9.4E-6,99.286518,0.93001018,,0,1868.4605,1.358,1868.4605,1.358,0.3073804,21.945654,,,,,1,,,,8.5140341E-5,41.297749,9857.8127,,0
20613496.75,,5905,105.056,104.715,0.588,9.4E-6,104.27449,0.97392357,,0,2070.6163,1.412,2070.6163,1.412,0.076579124,23.300944,,,,,1,,,,8.8864054E-5,43.891308,10873.169,,0
20614038.23,,5905,110.052,109.738,0.588,9.4E-6,109.28694,1.0249123,,0,2280.6917,1.623,2280.6917,1.623,4.735005,24.831124,,,,,1,,,,9.1848106E-5,46.601887,11943.636,,0
20614592.27,,5905,115.04,114.752,0.588,9.3E-6,114.28498,1.0775131,,0,2503.7048,1.545,2503.7048,1.545,0.48435451,26.235575,,,,,1,,,,9.543167E-5,49.662247,13061.058,,0
20615155.34,,5905,120.037,119.794,0.588,9.4E-6,119.2732,1.128984,,0,2724.4267,1.667,2724.4267,1.667,1.5825495,27.506861,,,,,1,,,,9.9045354E-5,52.471151,14226.096,,0
20615915.64,,5905,135.016,134.993,0.588,9.4E-6,134.2244,1.3265947,,0,3424.8091,3.262,3424.8091,3.262,3.5540967,31.434005,,,,,1,,,,0.00010895236,62.766754,18016.189,,0
20616513.25,,5905,146.803,146.968,0.588,9.3E-6,145.92381,1.3688592,,0,3950.3489,3.996,3950.3489,3.996,0.086401098,34.085368,,,,,1,,,,0.00011589574,62.868011,21293.758,,0
20617136.63,,5905,158.594,158.838,0.588,9.4E-6,157.63543,1.498565,,0,4473.1506,5.298,4473.1506,5.298,0.09493296,36.141574,,,,,1,,,,0.00012376745,68.170735,24848.93,,0
20617821.64,,5905,170.373,170.716,0.588,9.4E-6,169.41149,1.6155881,,0,4995.0611,5.652,4995.0611,5.652,0.093257645,37.5634,,,,,1,,,,0.00013297681,72.283148,28700.254,,0
20618556.77,,5905,182.153,182.51,0.588,9.3E-6,181.18741,1.7348057,,0,5479.7455,5.07,5479.7455,5.07,0.058674139,38.620164,,,,,1,,,,0.0001418882,75.1268,32828.877,,0
20619265.39,,5905,193.943,194.292,0.588,9.3E-6,192.89089,1.8520382,,0,5971.2442,6.596,5971.2442,6.596,0.083491529,39.57207,,,,,1,,,,0.00015089542,77.240329,37206.897,,0
20620023.22,,5905,205.727,206.088,0.588,9.4E-6,204.65629,1.9694874,,0,6462.3637,8.519,6462.3637,8.519,0.10918011,40.12301,,,,,1,,,,0.00016106378,79.144139,41884.196,,0
20620785.81,,5905,217.521,217.838,0.588,9.4E-6,216.41548,2.0869419,,0,6948.0479,10.77,6948.0479,10.77,0.150761,40.601492,,,,,1,,,,0.0001711279,80.246021,46835.659,,0
20621519.02,,5905,229.294,229.669,0.588,9.3E-6,228.21114,2.2115012,,0,7426.7176,11.94,7426.7176,11.94,0.11686289,41.010087,,,,,1,,,,0.0001810949,81.202983,52080.323,,0
20622330.56,,5905,241.086,241.417,0.588,9.4E-6,240.10231,2.3356521,,0,7856.0336,11.37,7856.0336,11.37,0.11977534,40.405688,,,,,1,,,,0.0001944289,82.020173,57649.12,,0
20623052.39,,5905,252.865,253.225,0.588,9.4E-6,251.90891,2.4428562,,0,8229.9706,10.46,8229.9706,10.46,0.097526498,39.742087,,,,,1,,,,0.00020708451,80.811376,63458.099,,0
20623773.25,,5905,264.652,265.008,0.588,9.4E-6,263.6874,2.5506108,,0,8577.2657,10.1,8577.2657,10.1,0.093034668,38.887136,,,,,1,,,,0.0002205682,79.484175,69531.042,,0
20624488.47,,5905,276.429,276.855,0.588,9.4E-6,275.48881,2.634966,,0,8968.3752,13.09,8968.3752,13.09,0.23851936,37.939587,,,,,1,,,,0.00023638568,77.774271,75894.083,,0
20625174.05,,5905,288.214,288.656,0.588,9.4E-6,287.20329,2.7185889,,0,9345.7411,18.13,9345.7411,18.13,0.29603002,37.058104,,,,,1,,,,0.00025219156,75.879174,82485.731,,0
20625893.89,,5905,299.996,300.444,0.588,9.4E-6,298.85692,2.8426947,,0,9501.5076,8.155,9501.5076,8.155,0.04299634,35.443295,,,,,1,,,,0.0002680763,74.116208,89315.459,,0