File: fork_ISISA_1906.txt
[Header]
TITLE,H20250619(ISISA HPHT 475C 6GPa 3.5h YBCO7).dat
BYAPP,HeatCapacity,3.9.11,1.7
INFO,17.43,MASS:Sample Mass (mg)
INFO,0.1,MASSERR:Sample Mass Error (mg)
INFO,666.22,MOLWGHT:Formula Weight (g/mole)
INFO,13,ATOMS:Atoms per Formula Unit
INFO,PPMS Heat Capacity Option 3.9.11 Build 2,APPNAME
DATATYPE,TIME,1
DATATYPE,COMMENT,2
STARTUPAXIS, X, 8, LINEAR, AUTO
STARTUPAXIS, Y1, 10, LINEAR, AUTO
[Data]
Time Stamp (Seconds),Comment (),System Status (Code),Puck Temp (Kelvin),System Temp (Kelvin),Field (Oersted),Pressure (Torr),Sample Temp (Kelvin),Temp Rise (Kelvin),Samp HC (mJ/mole-K),Samp HC Err (mJ/mole-K),Addenda HC (�J/K),Addenda HC Err (�J/K),Total HC (�J/K),Total HC Err (�J/K),Fit Deviation (ChiSquare),Time Const tau1 (seconds),Time Const tau2 (seconds),Sample Coupling (Percent),Debye Temp (Kelvin),Debye Temp Err (Kelvin),Cal Correction (Factor),Therm Resist (Ohms),Htr Resist (Ohms),Puck Resist (Ohms),Wire Cond (W/K),Meas Time (seconds),Temp Squared (K^2),Samp HC/Temp (mJ/mole-K/K),Addenda Offset HC (�J/K)
22042974.38,CALFILE: C:\QdPpms\HEATCA~1\TempCal\Standard\Puck1171.cal|Addenda #164 measured on 6/19/2025 from 1.987 to 298.1 K
22042974.48,,5905,2.00194,1.9914,0.325,9.4E-6,2.0328065,0.023512777,57.410472,0.3436,0.30901853,0.0009859,1.8110217,0.002557,3.2310744,1.1144749,0.0049695849,96.809057,154.63011,0.3838,1,,,,1.6620114E-6,2.2308313,4.1323022,28.241976,0
22043003.5,,5905,2.00163,1.9911,0.325,9.4E-6,2.0329146,0.023670484,57.431198,0.35,0.30909245,0.0009861,1.8116378,0.00309,0.48653271,1.1369057,0.0050252908,96.837059,154.61973,0.4019,1,,,,1.6294459E-6,2.2289498,4.1327419,28.250669,0
22043036.91,,5905,2.00126,1.9911,0.325,9.4E-6,2.0335952,0.023780697,56.739085,0.3439,0.3093254,0.0009867,1.7937633,0.002905,0.74648788,1.078235,0.0045780575,96.989811,155.29786,0.3986,1,,,,1.6991249E-6,2.2738114,4.1355094,27.900875,0
22043325.59,,5905,2.1668,2.1593,0.325,9.1E-6,2.1947465,0.024905955,59.021497,0.3466,0.38234578,0.001258,1.9264974,0.00194,2.9695049,1.0755539,0.0050787661,97.00461,165.41544,0.386,1,,,,1.8268733E-6,2.1564699,4.816912,26.892171,0
22043354.97,,5905,2.16652,2.159,0.325,9.1E-6,2.1945758,0.025088075,58.891044,0.3526,0.38229547,0.001258,1.9230341,0.002635,2.7475852,1.0942116,0.0051826168,96.999291,165.52462,0.4112,1,,,,1.7925303E-6,2.1511079,4.8161631,26.834819,0
22043383.94,,5905,2.16633,2.1588,0.325,9.4E-6,2.1943534,0.025097879,59.115471,0.3479,0.38216684,0.001257,1.928777,0.002025,1.9226299,1.0763075,0.0050421967,97.024663,165.29813,0.3887,1,,,,1.8275356E-6,2.1884232,4.8151869,26.939813,0
22043688.81,,5905,2.35147,2.3194,0.325,9.1E-6,2.3768762,0.0268181,60.084881,0.405,0.47471349,0.001878,2.0466859,0.00556,0.81463657,1.0078206,0.0050899809,97.149102,178.07922,0.5503,1,,,,2.0661413E-6,2.152615,5.6495404,25.278928,0
22043717.55,,5905,2.3492,2.3182,0.325,9.1E-6,2.3731353,0.025459131,61.911166,0.3966,0.47264055,0.001861,2.0923932,0.004616,0.12596355,1.0233924,0.004362888,97.549256,176.03321,0.5039,1,,,,2.0754809E-6,2.0156412,5.631771,26.088343,0
22043745.88,,5905,2.34598,2.32,0.325,9.3E-6,2.3695298,0.025293574,62.262998,0.5613,0.47069032,0.001845,2.0996478,0.01133,0.0072172301,1.0083844,0.0045471009,97.39246,175.43407,0.7401,1,,,,2.115899E-6,2.0467848,5.6146715,26.27652,0
22044078.61,,5905,2.54841,2.4996,0.325,9.3E-6,2.5691803,0.027032345,64.481794,0.4949,0.59056703,0.002515,2.2775738,0.008599,3.406775,0.97993146,0.0032093753,98.291674,188.00844,0.678,1,,,,2.3464535E-6,2.0167688,6.6006874,25.098197,0
22044110.39,,5905,2.54693,2.4948,0.325,9.3E-6,2.5675411,0.027353621,61.901664,0.421,0.5894816,0.002512,2.2089857,0.005914,0.11848482,0.97421704,0.0034915619,98.165283,190.46349,0.5958,1,,,,2.2903085E-6,1.9598629,6.5922671,24.109318,0
22044139.45,,5905,2.54551,2.4983,0.325,9.3E-6,2.5643762,0.027805187,60.236881,0.5562,0.58742009,0.002506,2.1633692,0.0114,0.026536532,0.98296226,0.004179077,97.847278,191.96528,0.8276,1,,,,2.2266735E-6,1.9484341,6.5760253,23.489877,0
22047385.34,,5905,2.74842,2.7458,0.325,9.1E-6,2.7576053,0.028915629,66.537657,0.4024,0.72971036,0.002699,2.4705037,0.003329,1.3033866,1.0391793,0.0053420484,97.529761,199.69694,0.5095,1,,,,2.4074133E-6,1.9659245,7.6043869,24.128782,0
22047414.52,,5905,2.7485,2.7461,0.325,9.3E-6,2.7579773,0.029788425,66.852185,0.4039,0.7301047,0.002699,2.4791269,0.00331,1.4899409,1.0451548,0.005535894,97.450201,199.41016,0.5075,1,,,,2.4030768E-6,2.0783587,7.606439,24.23957,0
22047444.2,,5905,2.74847,2.7459,0.325,9.3E-6,2.7579852,0.029846362,66.853401,0.4042,0.73009615,0.002699,2.4791502,0.003337,1.7145809,1.0394759,0.0052852834,97.552348,199.40952,0.5085,1,,,,2.4149396E-6,2.0903095,7.6064821,24.239942,0
22047757.91,,5905,2.97508,2.9749,0.325,9.3E-6,2.9801225,0.031548989,70.347668,0.4274,0.92999092,0.002864,2.7704638,0.003681,1.7167521,1.0623925,0.0056457981,97.623034,211.84229,0.5467,1,,,,2.6359322E-6,2.0789518,8.8811301,23.60563,0
22047787.39,,5905,2.97506,2.9751,0.325,9.1E-6,2.9801741,0.031934828,70.237685,0.4258,0.93006245,0.002864,2.7676579,0.003598,1.6168389,1.0573083,0.0054622083,97.690414,211.95647,0.544,1,,,,2.6450697E-6,2.1247849,8.8814374,23.568316,0
22047817.2,,5905,2.97487,2.9749,0.325,9.3E-6,2.9800776,0.03176937,70.32186,0.4258,0.9299315,0.002864,2.7697292,0.003562,1.0490978,1.0527243,0.0053290412,97.735771,211.86501,0.5423,1,,,,2.6580433E-6,2.1146167,8.8808626,23.597325,0
22048139.22,,5905,3.22017,3.2235,0.325,9.3E-6,3.223621,0.033363493,74.676028,0.4489,1.1921682,0.003131,3.145882,0.003507,1.2220987,1.0910903,0.0059681175,97.687721,224.63608,0.5644,1,,,,2.9097143E-6,2.1054485,10.391732,23.165263,0
22048168.25,,5905,3.22023,3.2238,0.325,9.1E-6,3.2238359,0.034103447,74.700502,0.4496,1.1925317,0.003131,3.1468857,0.003557,1.0490423,1.0946931,0.0061726644,97.61669,224.62652,0.5663,1,,,,2.9018989E-6,2.1821806,10.393118,23.171311,0
22048197.44,,5905,3.22012,3.2236,0.325,9.4E-6,3.2237043,0.034209287,74.629245,0.4496,1.1923877,0.003131,3.1448775,0.00359,1.3750294,1.0944082,0.0060480349,97.664462,224.68881,0.5678,1,,,,2.9002236E-6,2.1893863,10.392269,23.150152,0
22048523.98,,5905,3.48589,3.4913,0.325,9.1E-6,3.484982,0.035618422,81.153764,0.4975,1.5150003,0.003968,3.638188,0.004585,2.0298323,1.1537406,0.0068382406,97.579447,236.20704,0.6221,1,,,,3.1801851E-6,2.1888164,12.145099,23.28671,0
22048554.42,,5905,3.48612,3.4914,0.325,9.4E-6,3.4857035,0.036740568,81.179428,0.4965,1.5161234,0.003971,3.6399825,0.0045,1.4483503,1.1511152,0.0067586308,97.602187,236.23104,0.6189,1,,,,3.1887409E-6,2.3074813,12.150129,23.289252,0
22048584.63,,5905,3.48612,3.4912,0.325,9.4E-6,3.4859895,0.036742211,80.830883,0.4959,1.5164538,0.003972,3.6311941,0.004595,0.8977019,1.144278,0.0062657451,97.76446,236.58951,0.6241,1,,,,3.1980975E-6,2.3022305,12.152123,23.187357,0
22048915.97,,5905,3.77261,3.7826,0.325,9.4E-6,3.7674929,0.037857884,88.632591,0.5486,1.933835,0.004442,4.2526877,0.005384,0.63471827,1.2212308,0.007161818,97.656992,247.9609,0.6664,1,,,,3.5072842E-6,2.2885559,14.194003,23.525616,0
22048945.77,,5905,3.77321,3.7832,0.325,9.3E-6,3.7689317,0.039439289,88.121573,0.5436,1.9364319,0.00444,4.2419151,0.005224,0.60234114,1.2108305,0.0067353572,97.778112,248.53416,0.6633,1,,,,3.5269586E-6,2.4424616,14.204846,23.381048,0
22048975.94,,5905,3.77341,3.7833,0.325,9.4E-6,3.7689934,0.039174709,88.601798,0.5457,1.9365152,0.00444,4.2545623,0.005193,1.1936016,1.2165259,0.0069216852,97.72657,248.08839,0.66,1,,,,3.5215955E-6,2.421661,14.205311,23.50808,0
22049318.41,,5905,4.08489,4.0954,0.325,9.4E-6,4.0758307,0.040312459,98.081702,0.6049,2.471976,0.004836,5.0380414,0.005804,1.8082269,1.3106789,0.0083460713,97.482548,259.3475,0.6918,1,,,,3.8697594E-6,2.4330518,16.612396,24.064224,0
22049351.78,,5905,4.08457,4.0951,0.325,9.3E-6,4.076806,0.042377316,97.697851,0.5985,2.4708966,0.004832,5.0269194,0.005488,1.6150628,1.2885726,0.0062263637,98.084394,259.74885,0.683,1,,,,3.9209477E-6,2.6213577,16.620348,23.964312,0
22049382.83,,5905,4.08482,4.0957,0.325,9.4E-6,4.0764978,0.041742952,98.117698,0.6109,2.4734339,0.004841,5.0404411,0.006206,0.35439128,1.2998904,0.0075704382,97.695233,259.35822,0.7052,1,,,,3.9014556E-6,2.5771452,16.617834,24.069116,0
22050554.28,,5905,4.42776,4.4368,0.325,9.3E-6,4.4193799,0.042903934,111.31308,0.7556,3.1277468,0.009282,6.0399785,0.01056,0.84927076,1.4107237,0.0094562202,97.353034,269.59254,0.8411,1,,,,4.3087219E-6,2.5997808,19.530919,25.187489,0
22050587.92,,5905,4.42734,4.4361,0.325,9.4E-6,4.4201943,0.045412658,111.41484,0.7439,3.1264658,0.009272,6.0413598,0.009955,1.7124723,1.4119793,0.0094856015,97.347329,269.5601,0.8221,1,,,,4.3059731E-6,2.8214474,19.538118,25.20587,0
22050621.84,,5905,4.42531,4.4355,0.325,9.3E-6,4.4169307,0.04558199,112.53613,0.7611,3.1201561,0.009222,6.0643859,0.01054,2.6456864,1.4400874,0.01033332,97.16995,268.46346,0.8335,1,,,,4.2402427E-6,2.8239585,19.509277,25.478356,0
22050838.34,,5905,4.78439,4.8073,0.325,9.1E-6,4.774192,0.046981028,127.35895,0.9115,3.8878226,0.01338,7.2198549,0.01426,1.2741363,1.5213171,0.0087899435,97.705513,278.45308,0.9288,1,,,,4.7696685E-6,2.8801748,22.792909,26.676546,0
22050872.72,,5905,4.78514,4.8084,0.325,9.4E-6,4.7759558,0.048651236,126.25954,0.9064,3.8921215,0.01339,7.1953903,0.01425,1.1772619,1.5151274,0.0078254593,97.944711,279.36211,0.9351,1,,,,4.7701456E-6,3.0426342,22.809754,26.436496,0
22050907.41,,5905,4.78621,4.8094,0.325,9.3E-6,4.7766786,0.048628296,126.3684,0.9057,3.8939541,0.0134,7.200071,0.0142,1.3075769,1.5302373,0.009187759,97.61536,279.32413,0.9332,1,,,,4.7295813E-6,3.0302547,22.816658,26.455287,0
22051137.77,,5905,5.17785,5.2052,0.325,9.3E-6,5.1649988,0.05037397,147.8272,1.082,4.8420221,0.01582,8.7095555,0.01758,0.48368685,1.7313077,0.013634451,96.87,286.64698,0.9815,1,,,,5.0629304E-6,3.0604746,26.677213,28.620956,0
22051172.47,,5905,5.18007,5.2078,0.325,9.3E-6,5.1704067,0.053597224,148.87096,1.063,4.8567658,0.01585,8.7516066,0.01653,1.778428,1.6918353,0.011110533,97.382784,286.27492,0.9517,1,,,,5.2005661E-6,3.4626154,26.733105,28.792892,0
22051207.45,,5905,5.18149,5.2091,0.325,9.1E-6,5.1722377,0.052925111,147.44708,1.055,4.8612003,0.01586,8.7187889,0.0165,2.2370834,1.67634,0.010453013,97.510336,287.29519,0.9583,1,,,,5.2272461E-6,3.3836707,26.752043,28.507406,0
22051431.44,,5905,5.60615,5.6399,0.325,9.3E-6,5.5933872,0.053828494,171.24751,1.195,6.0542759,0.01714,10.534544,0.01781,1.6900111,1.8504933,0.012769761,97.226386,295.57115,0.9561,1,,,,5.7224092E-6,3.3526799,31.28598,30.616065,0
22051469.05,,5905,5.6089,5.642,0.325,9.4E-6,5.5964637,0.057127403,174.29153,1.225,6.0599999,0.01715,10.619907,0.01849,0.56403661,1.8622994,0.0129874,97.203628,294.00192,0.959,1,,,,5.7330363E-6,3.7009867,31.320406,31.143154,0
22051508.78,,5905,5.60943,5.6423,0.325,9.3E-6,5.5984107,0.057500894,170.74012,1.188,6.0654098,0.01715,10.532403,0.0176,1.5292984,1.8257866,0.009594048,97.877664,296.12936,0.9547,1,,,,5.7913129E-6,3.7245988,31.342203,30.497962,0
22051747.36,,5905,6.0718,6.1043,0.325,9.4E-6,6.0526926,0.057698657,203.2107,1.442,7.5296071,0.01966,12.846113,0.02222,0.41738079,2.0629439,0.014969581,97.066051,302.10723,0.9973,1,,,,6.2595538E-6,3.6515732,36.635087,33.573603,0
22051785.84,,5905,6.07239,6.1057,0.325,9.1E-6,6.0565515,0.062288451,204.50163,1.423,7.5385651,0.01968,12.888845,0.02107,0.53966169,2.0380704,0.013171299,97.383647,301.66277,0.9723,1,,,,6.3535115E-6,4.1258878,36.681816,33.765358,0
22051829.25,,5905,6.07218,6.1077,0.325,9.4E-6,6.0518921,0.062827982,210.60526,1.609,7.5259664,0.01965,13.035933,0.0278,1.2191515,2.2435575,0.031855879,94.388809,298.49014,1.071,1,,,,5.872993E-6,4.0761408,36.625398,34.799904,0
22052063.22,,5905,6.5724,6.6082,0.325,9.3E-6,6.5532412,0.066547648,245.86022,1.74,9.3283442,0.02535,15.760669,0.02668,0.84362981,2.2355606,0.012648832,97.693597,306.96486,1.011,1,,,,7.077867E-6,4.4871151,42.94497,37.517347,0
22052101.97,,5905,6.57406,6.61,0.325,9.3E-6,6.5547758,0.066558402,245.71331,1.741,9.3343806,0.02537,15.762862,0.02674,0.91971964,2.2443924,0.013799609,97.496442,307.09793,1.012,1,,,,7.0534019E-6,4.4711211,42.965086,37.48615,0
22052141.06,,5905,6.5754,6.6121,0.325,9.3E-6,6.5561631,0.066640453,245.41813,1.735,9.3396759,0.02539,15.760435,0.0265,1.3173494,2.23872,0.01437866,97.385919,307.28602,1.01,1,,,,7.0714986E-6,4.4887847,42.983274,37.433196,0
22052378.02,,5905,7.11539,7.1536,0.325,9.3E-6,7.0878934,0.067706547,297.61426,2.216,11.47275,0.03512,19.259092,0.03695,0.47192696,2.4939575,0.017724717,97.106264,311.5261,1.087,1,,,,7.7601864E-6,4.4774401,50.238233,41.989099,0
22052419.06,,5905,7.11817,7.1567,0.325,9.4E-6,7.0923465,0.072471992,299.14302,2.206,11.487346,0.03519,19.313684,0.03624,1.4412879,2.493017,0.017581314,97.130106,311.1899,1.074,1,,,,7.7849683E-6,4.987915,50.301379,42.178286,0
22052458.98,,5905,7.11863,7.1566,0.325,9.3E-6,7.0929965,0.072404616,298.12176,2.201,11.489468,0.0352,19.289087,0.03623,0.8401692,2.4678528,0.014538384,97.593513,311.57339,1.077,1,,,,7.8478414E-6,4.9860339,50.310599,42.03044,0
22052699.56,,5905,7.70383,7.7448,0.325,9.4E-6,7.6717834,0.073246277,365.40422,2.752,14.063127,0.04527,23.623026,0.04663,1.3390083,2.7379483,0.018065129,97.310569,314.89587,1.113,1,,,,8.6673156E-6,4.9357055,58.856261,47.629632,0
22052741.58,,5905,7.70576,7.7457,0.325,9.4E-6,7.6761637,0.077927001,368.73809,2.778,14.086672,0.04533,23.733793,0.04711,1.9903825,2.7768239,0.019917946,97.084557,314.12323,1.111,1,,,,8.5898149E-6,5.4758967,58.923489,48.036767,0
22052782.3,,5905,7.70655,7.7486,0.325,9.1E-6,7.6781465,0.078355738,366.89685,2.764,14.095418,0.04535,23.694367,0.04687,2.2402306,2.7330081,0.017733572,97.355203,314.72909,1.113,1,,,,8.7086102E-6,5.5536479,58.953934,47.78456,0
22053029.63,,5905,8.34139,8.3864,0.325,9.4E-6,8.3032519,0.079088241,455.54549,3.528,17.166847,0.0519,29.085069,0.06201,0.14507268,3.0869077,0.021725109,97.145019,316.66449,1.153,1,,,,9.4688996E-6,5.4660162,68.943993,54.863503,0
22053074.09,,5905,8.34389,8.388,0.325,9.1E-6,8.3085973,0.085177651,458.31692,3.36,17.18975,0.05195,29.180479,0.05472,1.0283097,3.063951,0.019221084,97.451957,316.22837,1.085,1,,,,9.566121E-6,6.1738153,69.03279,55.161768,0
22053118.56,,5905,8.34476,8.3901,0.325,9.1E-6,8.3101555,0.084775426,457.76894,3.341,17.197348,0.05197,29.173741,0.05402,0.72652688,3.0569732,0.018597197,97.527113,316.41382,1.08,1,,,,9.5843727E-6,6.1279019,69.058684,55.085484,0
22053370,,5905,9.03046,9.0785,0.325,9.4E-6,8.9903408,0.086144907,571.66304,4.133,20.83339,0.06338,35.789541,0.06581,1.2619605,3.408302,0.02167072,97.429739,317.87656,1.073,1,,,,1.0549382E-5,6.1139465,80.826227,63.58636,0
22053419.56,,5905,9.03312,9.0807,0.325,9.1E-6,8.9953137,0.092205833,576.15865,4.15,20.857332,0.06346,35.931099,0.06564,1.4026629,3.4325328,0.021684559,97.44853,317.22303,1.066,1,,,,1.0516354E-5,6.8166041,80.915668,64.050979,0
22053469.41,,5905,9.03476,9.0825,0.325,9.3E-6,8.9978652,0.092422304,572.35025,4.139,20.870761,0.06351,35.844891,0.0659,0.76234161,3.3934528,0.019007114,97.731109,318.01523,1.074,1,,,,1.0605993E-5,6.8650655,80.961578,63.609561,0
22053726.88,,5905,9.77682,9.8303,0.325,9.3E-6,9.7311317,0.093176049,719.86214,5.152,25.172544,0.07575,44.005958,0.08059,0.54923203,3.8252823,0.024161684,97.461232,318.6218,1.063,1,,,,1.1559215E-5,6.7869056,94.694925,73.975171,0
22053774.61,,5905,9.77948,9.833,0.325,9.3E-6,9.7377245,0.10030558,724.34822,5.136,25.209046,0.07581,44.159827,0.07898,1.3188601,3.8043076,0.023579868,97.509507,318.17808,1.05,1,,,,1.166279E-5,7.6505647,94.823278,74.385779,0
22053822.7,,5905,9.78163,9.8347,0.325,9.4E-6,9.7398524,0.099963386,725.45177,5.12,25.221759,0.07584,44.201412,0.07802,1.3765327,3.8010949,0.02304254,97.563688,318.08616,1.043,1,,,,1.1682468E-5,7.6086152,94.864724,74.48283,0
22054086.38,,5905,10.5856,10.6433,0.325,9.4E-6,10.533891,0.10103823,922.05538,6.315,30.339885,0.08347,54.463186,0.09023,0.80155392,4.297903,0.029319767,97.280626,317.58872,1.003,1,,,,1.2742012E-5,7.6021898,110.96285,87.532271,0
22054137.81,,5905,10.5889,10.6451,0.325,9.4E-6,10.541442,0.10919213,920.54146,6.263,30.386495,0.08357,54.470187,0.08807,1.1632878,4.2549556,0.025283409,97.62555,317.99053,0.9952,1,,,,1.2862822E-5,8.595806,111.12201,87.325949,0
22054189.89,,5905,10.59,10.6481,0.325,9.1E-6,10.542857,0.10843745,921.95962,6.263,30.394897,0.08359,54.515692,0.08772,1.092492,4.2409176,0.023312699,97.801312,317.87004,0.9927,1,,,,1.2911581E-5,8.5099111,111.15183,87.448748,0
22054461.63,,5905,11.4595,11.5203,0.325,9.3E-6,11.402335,0.1089955,1176.9816,8.103,36.39503,0.1081,67.187845,0.1172,0.57542283,4.7897591,0.030211902,97.495945,316.90748,1.007,1,,,,1.4103553E-5,8.4818351,130.01323,103.22286,0
22054515.41,,5905,11.4629,11.5251,0.325,9.3E-6,11.41025,0.1179844,1174.8113,8.038,36.449395,0.1084,67.185429,0.1146,0.50204952,4.7738285,0.02599841,97.833208,317.32264,1.001,1,,,,1.4139294E-5,9.5795182,130.1938,102.96105,0
22054569.39,,5905,11.4655,11.5262,0.325,9.1E-6,11.412478,0.11752238,1177.6757,8.021,36.465175,0.1085,67.27615,0.1131,1.3359007,4.7664671,0.026673053,97.774637,317.12707,0.994,1,,,,1.4182229E-5,9.547657,130.24465,103.19194,0
22054849.08,,5905,12.407,12.4719,0.325,9.1E-6,12.343515,0.11812771,1496.5894,10.42,43.510148,0.1395,82.664712,0.1543,0.22703788,5.3431093,0.028811042,97.862445,316.66482,1.021,1,,,,1.5547502E-5,9.5329342,152.36236,121.245,0
22054907.2,,5905,12.412,12.4748,0.325,9.4E-6,12.351491,0.12679944,1510.8658,10.32,43.571549,0.1396,83.099621,0.1463,1.0479782,5.3813954,0.030759345,97.73643,315.86822,0.9932,1,,,,1.5523409E-5,10.686219,152.55932,122.32255,0
22054964.58,,5905,12.4141,12.4767,0.325,9.3E-6,12.35462,0.12708913,1513.2899,10.31,43.595315,0.1397,83.186805,0.1455,2.038114,5.3479148,0.02786683,97.934302,315.77946,0.9901,1,,,,1.5629708E-5,10.762791,152.63664,122.48777,0
22055252.83,,5905,13.4345,13.5023,0.325,9.1E-6,13.362674,0.12641327,1953.2492,12.97,51.871779,0.1571,102.97372,0.171,0.62499843,6.0744949,0.034093972,97.779902,313.69141,0.9494,1,,,,1.7047143E-5,10.69583,178.56105,146.17204,0
22055315.19,,5905,13.4386,13.5057,0.325,9.4E-6,13.372571,0.13752496,1940.4458,12.94,51.942982,0.1573,102.70995,0.1728,0.21949313,5.9889143,0.024661798,98.366302,314.61268,0.9583,1,,,,1.7219888E-5,12.14899,178.82566,145.10641,0
22055375.77,,5905,13.4408,13.5072,0.325,9.4E-6,13.373725,0.13618217,1957.3948,12.94,51.965666,0.1573,103.17606,0.1679,1.5004334,6.099138,0.034112461,97.787585,313.72903,0.9427,1,,,,1.701132E-5,11.977829,178.85651,146.36123,0
22055676.39,,5905,14.5461,14.613,0.325,9.4E-6,14.467356,0.1380948,2498.3429,16.39,61.725243,0.1775,127.08821,0.2077,0.22761123,6.8753672,0.034545683,98.007242,312.87179,0.9434,1,,,,1.8584492E-5,12.198276,209.30438,172.68829,0
22055743.47,,5905,14.5505,14.615,0.325,9.1E-6,14.476503,0.14888194,2509.9687,16.16,61.811349,0.1777,127.47848,0.1921,1.7172009,6.9028833,0.034362253,98.025302,312.58548,0.9025,1,,,,1.8566638E-5,13.750734,209.56913,173.38226,0
22055810.19,,5905,14.5518,14.6162,0.325,9.1E-6,14.478638,0.1483132,2506.0786,16.1,61.826954,0.1777,127.39231,0.1893,1.7425526,6.7559758,0.03022125,98.223992,312.79327,0.9131,1,,,,1.8946961E-5,13.805767,209.63095,173.08801,0
22056114.13,,5905,15.749,15.8218,0.325,9.3E-6,15.663187,0.14643805,3241.9795,20.91,73.184264,0.2058,158.00265,0.2498,0.17170444,7.8264154,0.039681375,97.978144,310.55304,0.8988,1,,,,2.0309048E-5,13.511952,245.33543,206.98083,0
22056186.83,,5905,15.7527,15.8248,0.325,9.1E-6,15.674996,0.16083371,3252.0148,20.65,73.29301,0.2061,158.37394,0.2314,0.48482904,7.8057302,0.037134289,98.101673,310.46713,0.8754,1,,,,2.0403299E-5,15.652831,245.70549,207.46511,0
22056258.44,,5905,15.7563,15.8281,0.325,9.3E-6,15.67801,0.16031164,3256.4502,20.67,73.321421,0.2062,158.51839,0.2314,0.35490807,7.7916029,0.036250325,98.143028,310.38576,0.8747,1,,,,2.0456491E-5,15.61146,245.79999,207.70814,0
22056576.27,,5905,17.0502,17.1286,0.325,9.4E-6,16.959327,0.16006157,4212.5119,26.74,86.180463,0.2518,196.39043,0.2992,0.27535615,9.0169366,0.044349874,98.017151,308.13914,0.8685,1,,,,2.1919617E-5,15.583206,287.61879,248.38909,0
22056654.22,,5905,17.0553,17.132,0.325,9.4E-6,16.972184,0.17527166,4219.446,26.38,86.307249,0.2523,196.69863,0.2744,0.9281768,8.9294248,0.038823791,98.245712,308.20366,0.8453,1,,,,2.2152574E-5,18.033873,288.05502,248.60949,0
22056731.5,,5905,17.0576,17.1339,0.325,9.1E-6,16.974919,0.1742287,4201.7485,26.22,86.331735,0.2524,196.2601,0.2698,2.6982387,8.8243038,0.035694797,98.368114,308.68565,0.8434,1,,,,2.2357088E-5,17.85885,288.14787,247.52687,0
22057060.72,,5905,18.4583,18.5451,0.325,9.4E-6,18.364298,0.17288587,5403.7208,34.12,101.59905,0.317,242.97405,0.3729,0.46521263,10.32067,0.048858693,98.066172,307.07269,0.8582,1,,,,2.3700392E-5,17.648608,337.24743,294.25142,0
22057149,,5905,18.4666,18.5493,0.325,9.4E-6,18.379859,0.19068938,5410.0549,33.91,101.7647,0.3178,243.30542,0.3571,0.73015711,10.213625,0.046264303,98.149331,307.21279,0.8469,1,,,,2.3974359E-5,20.641341,337.8192,294.34693,0
22057236.05,,5905,18.4682,18.553,0.325,9.1E-6,18.38299,0.18963366,5405.9188,33.67,101.79789,0.318,243.23039,0.3429,1.9890493,10.185049,0.041766343,98.323966,307.34354,0.8372,1,,,,2.4019331E-5,20.42725,337.93431,294.07179,0
22057579.69,,5905,19.9848,20.0767,0.325,9.4E-6,19.88266,0.18827254,6886.0341,43.61,119.57597,0.3917,299.73203,0.4833,0.19342842,11.738634,0.051067581,98.194637,306.61733,0.8626,1,,,,2.5704154E-5,20.370097,395.32019,346.33363,0
22057673.84,,5905,19.9924,20.0817,0.325,9.3E-6,19.898931,0.20626726,6903.1384,42.98,119.75898,0.3922,300.36254,0.4367,1.3377285,11.650161,0.047677435,98.300861,306.61402,0.8357,1,,,,2.5943622E-5,23.477267,395.96747,346.91001,0
22057767.7,,5905,19.9952,20.0848,0.325,9.4E-6,19.902885,0.20519393,6877.9995,42.66,119.8017,0.3924,299.74756,0.4244,1.9689066,11.530955,0.04400386,98.416416,307.04896,0.8308,1,,,,2.6146356E-5,23.300321,396.12484,345.57801,0
22058228.19,,5905,22.9899,23.0873,0.325,9.3E-6,22.880616,0.22889551,10389.82,62.8,157.11872,0.4361,428.94269,0.5174,2.0779162,14.712325,0.056155935,98.360788,307.44096,0.7901,1,,,,2.9351204E-5,27.34078,523.52258,454.0883,0
22058341.06,,5905,22.9952,23.0915,0.325,9.1E-6,22.891705,0.23771311,10393.653,62.72,157.24888,0.4362,429.17312,0.5087,2.8744321,14.573961,0.051114467,98.493603,307.55184,0.787,1,,,,2.9629387E-5,29.424651,524.03015,454.03576,0
22058452.95,,5905,22.9976,23.0934,0.325,9.1E-6,22.893315,0.23576795,10411.824,62.75,157.26614,0.4362,429.6658,0.5028,1.5297646,14.510841,0.051957177,98.461503,307.39294,0.7841,1,,,,2.9796618E-5,29.147923,524.10387,454.79758,0
22058886.77,,5905,26.2374,26.3515,0.325,9.4E-6,26.10447,0.23783131,14938.407,92.05,200.74888,0.5522,591.57538,0.8784,0.11371012,18.456849,0.069590549,98.321595,310.2436,0.8441,1,,,,3.2291526E-5,29.021682,681.44335,572.25475,0
22059021.83,,5905,26.2444,26.3568,0.325,9.1E-6,26.136708,0.27638028,14950.2,89.62,201.1752,0.5542,592.31024,0.6796,0.30492049,18.07413,0.060412489,98.512429,310.54327,0.7912,1,,,,3.2987681E-5,36.913698,683.12748,572.00012,0
22059155.5,,5905,26.2456,26.3601,0.325,9.3E-6,26.139334,0.27221935,14982.452,89.22,201.20339,0.5543,593.18223,0.6255,5.6082737,17.976571,0.058042367,98.561996,310.34662,0.7759,1,,,,3.3208428E-5,36.14826,683.26477,573.17652,0
22059691.59,,5905,29.4909,29.6282,0.325,9.1E-6,29.364525,0.26995563,20547.916,125.9,248.14872,0.7804,785.73418,1.154,0.24793063,21.873332,0.085114711,98.20095,312.74171,0.859,1,,,,3.6231288E-5,35.953141,862.27535,699.75305,0
22059847.67,,5905,29.4962,29.631,0.325,9.3E-6,29.389388,0.30433747,20647.286,123.4,248.47668,0.7818,788.6619,0.9002,0.42351998,21.411371,0.071695013,98.44966,312.48119,0.8065,1,,,,3.7106831E-5,43.746663,863.73615,702.54223,0
22060000.53,,5905,29.4973,29.6319,0.325,9.3E-6,29.390045,0.30003002,20611.628,123.6,248.48685,0.7818,787.73917,0.9449,0.17488098,21.250407,0.069389601,98.48913,312.67632,0.8162,1,,,,3.7336734E-5,42.822741,863.77476,701.31326,0
22060647.08,,5905,32.7455,32.8947,0.325,9.3E-6,32.608274,0.28667782,27049.19,162.9,298.04629,0.9548,1005.7215,1.298,2.7732323,22.85832,0.09264587,98.056373,315.16497,0.8573,1,,,,4.4431624E-5,42.500814,1063.2995,829.5192,0
22060807.7,,5905,32.7486,32.8945,0.325,9.4E-6,32.618463,0.29931821,27220.126,165.4,298.19417,0.9553,1010.3415,1.426,0.19678257,22.760174,0.092130429,98.054114,314.5513,0.8753,1,,,,4.4830231E-5,45.71664,1063.9642,834.50056,0
22060970.42,,5905,32.752,32.8921,0.325,9.3E-6,32.619899,0.29876861,27174.916,164,298.2127,0.9554,1009.1772,1.328,0.13752517,22.678193,0.086335758,98.171261,314.75297,0.8605,1,,,,4.4912905E-5,45.520348,1064.0578,833.07786,0
22061682.66,,5905,35.998,36.1395,0.325,9.1E-6,35.847039,0.31269395,33152.614,196.7,350.89123,1.096,1218.2474,1.314,7.0402776,27.925643,0.097240425,98.301342,321.71845,0.8651,1,,,,4.4008157E-5,45.356386,1285.0102,924.8355,0
22061875.03,,5905,35.9988,36.1474,0.325,9.1E-6,35.871289,0.35588525,33484.459,200.7,351.26284,1.097,1227.301,1.523,0.13193121,27.890433,0.093177253,98.363968,320.75001,0.8905,1,,,,4.4378534E-5,55.851286,1286.7494,933.46127,0
22062067.63,,5905,35.9986,36.1492,0.325,9.3E-6,35.871426,0.35550514,33404.97,200.4,351.26282,1.097,1225.2213,1.531,0.15176386,27.789221,0.094656976,98.333647,321.03406,0.8926,1,,,,4.4471265E-5,55.780867,1286.7592,931.24176,0
22062694,,5905,39.2435,39.4055,0.325,9.3E-6,39.091707,0.37165145,38986.712,240.3,406.69979,1.21,1426.6908,2.296,0.061229005,32.417128,0.10542013,98.403586,330.0961,1.009,1,,,,4.4376543E-5,55.578442,1528.1616,997.31414,0
22062913.86,,5905,39.2517,39.4061,0.325,9.1E-6,39.122942,0.4094485,38967.978,230.4,407.19978,1.211,1426.7006,1.461,0.16822834,31.774559,0.090900341,98.596776,330.42052,0.9067,1,,,,4.5227973E-5,64.834255,1530.6046,996.03906,0
22063129.67,,5905,39.2522,39.4042,0.325,9.4E-6,39.122832,0.40462153,38918.578,230.6,407.19702,1.211,1425.4054,1.512,0.077782756,31.65734,0.087442141,98.645932,330.57976,0.9133,1,,,,4.5342316E-5,63.549117,1530.596,994.77916,0
22063822.38,,5905,42.5005,42.6681,0.325,9.3E-6,42.350016,0.41009094,46040.563,277.6,465.68333,1.387,1670.2209,2.234,0.10271467,35.741574,0.11098747,98.454541,335.1811,1.013,1,,,,4.7113195E-5,63.314679,1793.5238,1087.1439,0
22064097.77,,5905,42.4991,42.6597,0.325,9.3E-6,42.373647,0.44298742,45613.269,268.6,466.07348,1.388,1659.4319,1.585,0.37655646,34.694276,0.09196825,98.686877,336.61176,0.9446,1,,,,4.8160149E-5,71.483149,1795.526,1076.4537,0
22064366.25,,5905,42.4991,42.6608,0.325,9.1E-6,42.365539,0.43704503,45620.928,269.2,465.94913,1.388,1659.508,1.645,0.28903772,35.125585,0.10177405,98.56435,336.52495,0.951,1,,,,4.7602003E-5,69.388553,1794.8389,1076.8405,0
22065038.11,,5905,45.7464,45.9311,0.325,9.1E-6,45.595932,0.45089428,52308.016,316,527.8976,1.56,1896.4076,2.592,0.068307968,39.086911,0.11937817,98.478463,342.71539,1.079,1,,,,4.8909288E-5,70.251171,2078.989,1147.208,0
22065299.55,,5905,45.751,45.9279,0.325,9.4E-6,45.623792,0.48127478,52247.622,308.1,528.37947,1.561,1895.3094,1.858,0.12467434,38.124149,0.10091138,98.682729,343.08799,1.004,1,,,,5.0060246E-5,78.173822,2081.5304,1145.1837,0
22065592.5,,5905,45.7514,45.9216,0.325,9.3E-6,45.619773,0.47461129,52220.024,307.3,528.3144,1.561,1894.5223,1.792,0.19866161,38.177997,0.10328718,98.653842,343.13241,0.9976,1,,,,4.9976499E-5,76.248299,2081.1637,1144.6796,0
22066341,,5905,49.0013,49.1965,0.325,9.4E-6,48.848879,0.48494005,59166.93,354,593.98959,1.69,2141.9461,2.628,0.087831702,42.029409,0.1272817,98.487716,348.64785,1.113,1,,,,5.1372985E-5,76.355994,2386.213,1211.2239,0
22066662.47,,5905,49.0023,49.1838,0.325,9.1E-6,48.870247,0.51446231,59033.565,349.6,594.37823,1.691,2138.8456,2.267,0.048334852,41.076612,0.10834938,98.684683,349.13775,1.079,1,,,,5.2432512E-5,84.058819,2388.301,1207.9654,0
22066977.56,,5905,48.9985,49.1853,0.325,9.1E-6,48.864353,0.5083229,59007.802,346.3,594.26124,1.69,2138.0546,1.91,0.22826106,41.240541,0.11389278,98.622986,349.1609,1.045,1,,,,5.2221961E-5,82.153224,2387.725,1207.5838,0
22067682.22,,5905,52.2477,52.4432,0.325,9.1E-6,52.086967,0.51830229,66188.86,400.6,664.14771,1.831,2395.8157,3.341,0.056122062,45.23613,0.13939609,98.460808,353.96423,1.214,1,,,,5.3396318E-5,82.481083,2713.0522,1270.7374,0
22068027.2,,5905,52.2524,52.4434,0.325,9.4E-6,52.11518,0.55013037,66018.192,387.2,664.70824,1.832,2391.9111,2.109,0.79395643,44.318492,0.12215865,98.625481,354.56436,1.103,1,,,,5.4364251E-5,90.472261,2715.992,1266.7747,0
22068363.89,,5905,52.2495,52.4421,0.325,9.4E-6,52.11301,0.54352761,65862.568,386.4,664.66751,1.832,2387.7989,2.115,0.393505,44.128722,0.12090313,98.635183,354.92295,1.104,1,,,,5.4500843E-5,88.636985,2715.7658,1263.8412,0
22069086.45,,5905,55.4963,55.7057,0.325,9.4E-6,55.334382,0.55333945,72581.91,437.6,738.72079,1.976,2637.6471,3.516,0.052484675,47.926163,0.1499448,98.447251,360.58191,1.272,1,,,,5.5486974E-5,88.257444,3061.8939,1311.6964,0
22069448.45,,5905,55.5038,55.7007,0.325,9.1E-6,55.36239,0.58279759,72510.423,424.9,739.29853,1.978,2636.3546,2.26,0.80917302,46.96165,0.12952808,98.632338,360.92933,1.162,1,,,,5.6542642E-5,95.852326,3064.9942,1309.7416,0
22069803.19,,5905,55.5019,55.6961,0.325,9.3E-6,55.357687,0.57479431,72676.114,426.6,739.19775,1.977,2640.5887,2.358,0.080272605,46.912735,0.13114112,98.612347,360.51674,1.17,1,,,,5.6699083E-5,93.9233,3064.4735,1312.8459,0
22070576.86,,5905,58.7536,58.9641,0.325,9.3E-6,58.582069,0.5862515,79298.846,477,817.36282,2.128,2892.0212,3.749,0.056243894,50.633005,0.16234041,98.417704,366.08836,1.336,1,,,,5.7591423E-5,93.825471,3431.8588,1353.6368,0
22070959.13,,5905,58.7509,58.9554,0.325,9.3E-6,58.60838,0.61464886,79278.458,464.5,817.94203,2.128,2892.067,2.463,0.22831867,49.632268,0.13917493,98.616853,366.29826,1.228,1,,,,5.8691438E-5,101.26601,3434.9422,1352.6813,0
22071332.58,,5905,58.7485,58.9507,0.325,9.4E-6,58.601924,0.60742854,79260.287,465.2,817.79428,2.128,2891.4438,2.561,0.092069323,49.603716,0.14033972,98.604497,366.29845,1.236,1,,,,5.8716387E-5,99.264536,3434.1855,1352.5202,0
22072115.63,,5905,62.0009,62.219,0.325,9.3E-6,61.827449,0.61726875,85882.15,518.3,900.43891,2.102,3147.3331,4.203,0.063696361,53.208218,0.17992958,98.343589,371.48762,1.423,1,,,,5.9660766E-5,99.207432,3822.6335,1389.0618,0
22072514.59,,5905,62.0016,62.2042,0.325,9.1E-6,61.851981,0.64537772,85940.163,502.1,900.99301,2.101,3149.405,2.479,0.17372915,52.055731,0.1459087,98.627139,371.50891,1.28,1,,,,6.0931079E-5,106.41644,3825.6676,1389.4488,0
22072906.19,,5905,61.9985,62.2057,0.325,9.4E-6,61.847527,0.63737593,85852.316,502.2,900.89083,2.101,3147.0045,2.558,0.1338301,52.07248,0.15111464,98.579154,371.67314,1.287,1,,,,6.0880112E-5,104.11146,3825.1166,1388.1285,0
22073759.72,,5905,65.2531,65.4806,0.325,9.3E-6,65.075198,0.64740273,92164.661,545.8,988.25257,2.067,3399.5132,3.543,0.058882491,55.169001,0.18025534,98.415077,377.11576,1.423,1,,,,6.2120894E-5,104.14496,4234.7814,1416.2794,0
22074171.27,,5905,65.2509,65.4625,0.325,9.3E-6,65.096278,0.67333863,92182.29,537.7,988.77415,2.068,3400.496,2.543,0.14807096,54.369812,0.16243944,98.55098,377.20024,1.342,1,,,,6.300778E-5,110.338,4237.5254,1416.0916,0
22074576.59,,5905,65.2509,65.4699,0.325,9.3E-6,65.093116,0.66746843,92261.358,539.2,988.70576,2.068,3402.4962,2.685,0.073430693,54.419606,0.16095229,98.564996,377.01261,1.353,1,,,,6.2982838E-5,108.73962,4237.1138,1417.375,0
22075396.17,,5905,68.4989,68.7317,0.325,9.1E-6,68.316268,0.67879341,98437.001,589.3,1080.9976,2.254,3656.3585,4.4,0.054189415,57.683476,0.19856763,98.346932,382.26228,1.549,1,,,,6.3916999E-5,108.83921,4667.1124,1440.9013,0
22075826.11,,5905,68.5009,68.7281,0.325,9.3E-6,68.342092,0.70573547,98414.301,573.9,1081.6794,2.255,3656.4464,2.689,0.18527306,56.683156,0.17868226,98.486785,382.45465,1.411,1,,,,6.4999777E-5,115.36695,4670.6416,1440.0247,0
22076252,,5905,68.5003,68.7246,0.325,9.4E-6,68.34024,0.69805201,98365.436,573.6,1081.6122,2.255,3655.1008,2.678,0.12725083,56.502453,0.17463168,98.51663,382.54738,1.411,1,,,,6.5173605E-5,113.36631,4670.3883,1439.3487,0
22077090.44,,5905,71.7491,71.9934,0.325,9.3E-6,71.558821,0.70875917,104442.64,629.4,1177.7972,2.422,3910.2807,5.037,0.049067366,59.856917,0.2164178,98.282685,387.50366,1.66,1,,,,6.5886569E-5,113.00491,5120.6649,1459.5354,0
22077534.52,,5905,71.7506,71.9886,0.325,9.4E-6,71.588272,0.73668712,104520.72,609.6,1178.5954,2.424,3913.1218,2.869,0.26980045,58.846776,0.18991408,98.46706,387.49983,1.487,1,,,,6.7003976E-5,119.71383,5124.8806,1460.0257,0
22077974.23,,5905,71.7499,71.9856,0.325,9.3E-6,71.586481,0.72896417,104388.5,610.8,1178.5424,2.423,3909.6095,3.136,0.041562844,58.565569,0.1838164,98.509888,387.76672,1.508,1,,,,6.7250425E-5,117.69355,5124.6242,1458.2153,0
22078831,,5905,74.9973,75.2529,0.325,9.3E-6,74.807095,0.73963699,110253.5,661.5,1278.9819,2.563,4163.4922,5.062,0.042711682,61.771678,0.22218512,98.31086,392.69625,1.725,1,,,,6.795919E-5,117.13114,5596.1015,1473.8374,0
22079290.81,,5905,74.9997,75.25,0.325,9.4E-6,74.835394,0.7671781,110231.03,643.2,1279.7988,2.564,4163.7214,3.065,0.13728748,60.719722,0.19799807,98.469108,392.89161,1.567,1,,,,6.9085932E-5,123.54336,5600.3361,1472.9799,0
22079744.39,,5905,75.0061,75.244,0.325,9.4E-6,74.833603,0.75879933,110218.16,643.3,1279.7476,2.564,4163.3333,3.098,0.084662907,60.540159,0.19594942,98.480495,392.90905,1.569,1,,,,6.9280462E-5,121.43944,5600.0681,1472.8431,0
22080612.09,,5905,75.9954,76.2497,0.325,9.4E-6,75.810804,0.74049658,111925.38,653.9,1311.2465,2.6,4239.4975,3.235,0.098178335,61.495321,0.21033087,98.399973,394.45923,1.6,1,,,,6.9476815E-5,114.38746,5747.2779,1476.3777,0
22081070.8,,5905,75.9983,76.2447,0.325,9.4E-6,75.833158,0.77031101,111888.96,652.9,1311.8611,2.6,4239.1593,3.123,0.19427461,61.159746,0.20045717,98.46716,394.65145,1.591,1,,,,6.9829113E-5,122.99064,5750.6678,1475.4622,0
22081527.36,,5905,75.9992,76.2439,0.325,9.4E-6,75.830315,0.76713151,112037.45,654.8,1311.7814,2.6,4242.9644,3.263,0.081247963,61.185883,0.20156985,98.458479,394.32734,1.602,1,,,,6.9865361E-5,122.31949,5750.2367,1477.4757,0
22082260.5,,5905,76.9915,77.2412,0.325,9.1E-6,76.808739,0.77030742,113756.69,681.7,1343.7169,2.633,4319.8795,5.15,0.047161905,62.941634,0.23406709,98.265971,395.81371,1.772,1,,,,6.9210117E-5,122.37177,5899.5824,1481.0383,0
22082726.73,,5905,77.0031,77.2481,0.325,9.1E-6,76.833998,0.78556287,113677.8,661.9,1344.4696,2.634,4318.5684,2.952,0.62761702,61.746098,0.2065141,98.441126,396.10814,1.598,1,,,,7.0467812E-5,125.88327,5903.4633,1479.5248,0
22083186.56,,5905,77.0019,77.2523,0.325,9.4E-6,76.82895,0.7761205,113719.26,663.5,1344.31,2.634,4319.4933,3.16,0.087286989,61.626948,0.20558366,98.444856,395.99579,1.614,1,,,,7.0618047E-5,123.4922,5902.6876,1480.1615,0
22083920.14,,5905,77.99,78.2502,0.325,9.1E-6,77.806924,0.77801838,115577.6,694.4,1376.6334,2.665,4400.4359,5.394,0.038699806,63.47184,0.23890295,98.250576,397.14516,1.812,1,,,,6.9914063E-5,123.2539,6053.9174,1485.4411,0
22084392.34,,5905,77.998,78.258,0.325,9.1E-6,77.831759,0.79466254,115442.67,672.5,1377.3892,2.666,4397.6612,3.053,0.36609497,62.344422,0.21228926,98.418282,397.55275,1.627,1,,,,7.1074727E-5,126.94368,6057.7828,1483.2334,0
22084857.75,,5905,78.0021,78.2442,0.325,9.3E-6,77.828632,0.7858395,115308.88,673.7,1377.2839,2.666,4394.0559,3.338,0.067614154,62.065133,0.20602804,98.458637,397.81547,1.649,1,,,,7.132167E-5,124.68884,6057.2959,1481.5741,0
22085598.39,,5905,78.992,79.2569,0.325,9.4E-6,78.808223,0.7872043,117145.29,703.7,1410.039,2.698,4474.8562,5.455,0.042947357,64.01422,0.23989331,98.26518,398.97313,1.838,1,,,,7.0485199E-5,124.13027,6210.736,1486.4603,0
22086074.44,,5905,79.004,79.2533,0.325,9.1E-6,78.833379,0.80447963,117079.04,682,1410.7939,2.698,4473.8777,3.082,0.22363334,62.897446,0.21314247,98.431795,399.23851,1.65,1,,,,7.1662752E-5,128.02844,6214.7017,1485.1455,0
22086541.28,,5905,79.0009,79.2517,0.325,9.2E-6,78.828415,0.79556741,117147.49,684.5,1410.6603,2.698,4475.5349,3.394,0.048553231,62.816264,0.21385857,98.424093,399.07078,1.675,1,,,,7.1784849E-5,125.79489,6213.9191,1486.1074,0
22087284.72,,5905,79.9962,80.2581,0.325,9.4E-6,79.806442,0.79758584,118848.74,715.8,1443.7152,2.733,4553.0989,5.699,0.041418153,64.507544,0.24585722,98.241775,400.45697,1.879,1,,,,7.1173826E-5,125.63253,6369.0681,1489.2124,0
22087762.39,,5905,80.0021,80.2561,0.325,9.3E-6,79.831206,0.81302392,118837.11,692.1,1444.4842,2.734,4553.5634,3.111,0.34816247,63.438216,0.22002952,98.4002,400.60547,1.673,1,,,,7.2325448E-5,129.01509,6373.0214,1488.6047,0
22088233.39,,5905,79.9998,80.2532,0.325,9.1E-6,79.82635,0.80454222,118767.2,694.2,1444.3205,2.734,4551.5709,3.467,0.06454807,63.190112,0.21353682,98.441554,400.72679,1.702,1,,,,7.2563052E-5,126.87643,6372.2462,1487.8195,0
22088983.5,,5905,80.9962,81.266,0.325,9.3E-6,80.80324,0.80585127,120548.27,724.4,1477.8053,2.783,4631.6529,5.641,0.047397358,65.135777,0.25458078,98.203148,401.8955,1.895,1,,,,7.1713322E-5,126.38022,6529.1635,1491.8742,0
22089467.13,,5905,81.0031,81.2517,0.325,9.4E-6,80.830773,0.82283899,120417.24,701.3,1478.6493,2.784,4629.0688,3.152,0.39409964,63.838705,0.222896,98.395625,402.30624,1.698,1,,,,7.3061513E-5,130.27155,6533.6138,1489.745,0
22089941.08,,5905,81.0013,81.2519,0.325,9.3E-6,80.82406,0.81284178,120449.89,703.2,1478.4442,2.784,4629.718,3.402,0.064956793,63.738752,0.21777732,98.42974,402.20419,1.718,1,,,,7.3174556E-5,127.67741,6532.5287,1490.2727,0
22090699.27,,5905,81.9909,82.2535,0.325,9.3E-6,81.805036,0.81518757,122169.17,733.5,1512.4695,2.837,4708.7239,5.656,0.056974889,65.589103,0.25706902,98.204674,403.47756,1.919,1,,,,7.2398378E-5,127.4775,6692.064,1493.4187,0
22091188.55,,5905,82.0039,82.2495,0.325,9.3E-6,81.831306,0.83109642,122126.89,711.5,1513.2711,2.838,4708.4193,3.233,0.28453499,64.260027,0.22292064,98.411261,403.69538,1.726,1,,,,7.3817988E-5,131.17821,6696.3627,1492.4226,0
22091665.73,,5905,81.9943,82.2514,0.325,9.4E-6,81.823979,0.82140992,122070.87,713.6,1513.0539,2.838,4706.7366,3.579,0.064118603,64.271989,0.22661328,98.385458,403.77619,1.753,1,,,,7.378681E-5,128.52005,6695.1635,1491.8716,0
22092421.94,,5905,82.9905,83.2569,0.325,9.1E-6,82.804501,0.8243457,123724.81,746.9,1547.3642,2.88,4784.3182,6.078,0.039092592,65.980311,0.26061165,98.197448,405.13889,1.974,1,,,,7.312303E-5,128.54398,6856.5853,1494.1798,0
22092911.47,,5905,83.0019,83.2547,0.325,9.3E-6,82.82827,0.83991482,123787.31,721.6,1548.1137,2.881,4786.7027,3.339,0.12033688,64.844361,0.22538374,98.413545,405.12456,1.756,1,,,,7.4364972E-5,131.96062,6860.5222,1494.5055,0
22093393.92,,5905,83.0034,83.2485,0.325,9.4E-6,82.823226,0.83144565,123683.2,722.7,1547.9489,2.881,4783.8141,3.586,0.051840081,64.741033,0.22554387,98.410311,405.31751,1.776,1,,,,7.443959E-5,129.68872,6859.6868,1493.3395,0
22094157.64,,5905,83.9955,84.2493,0.325,9.4E-6,83.805303,0.83271012,125449.11,749.2,1582.5191,2.899,4864.585,5.447,0.054271749,66.395097,0.25956323,98.221446,406.40886,1.946,1,,,,7.3873533E-5,129.48207,7023.3287,1496.9113,0
22094650.61,,5905,84.0032,84.2484,0.325,9.1E-6,83.827322,0.84874114,125329.17,730.9,1583.225,2.899,4862.1531,3.424,0.15921198,65.382073,0.23703166,98.351339,406.76664,1.785,1,,,,7.493424E-5,132.79019,7027.02,1495.0874,0
22095134.39,,5905,83.9991,84.2448,0.325,9.4E-6,83.823067,0.84105142,125272.99,731,1583.0873,2.899,4860.5455,3.497,0.1008235,65.260681,0.23375438,98.371296,406.86364,1.79,1,,,,7.5041633E-5,130.76415,7026.3065,1494.493,0
22095902.11,,5905,84.9962,85.239,0.325,9.3E-6,84.800744,0.84277089,126918.91,753.6,1617.6326,2.88,4938.1523,5.079,0.063928625,66.894558,0.26450818,98.20773,408.14032,1.939,1,,,,7.4431515E-5,130.52136,7191.1662,1496.6721,0
22096398.03,,5905,85.003,85.2284,0.325,9.4E-6,84.826003,0.85898514,126848.39,739.2,1618.4585,2.879,4937.133,3.383,0.17726874,65.96665,0.23994344,98.351738,408.40982,1.804,1,,,,7.5411677E-5,133.78912,7195.4508,1495.3951,0
22096887.55,,5905,85.0003,85.2249,0.325,9.3E-6,84.821229,0.85140057,126784.49,740.6,1618.2941,2.879,4935.297,3.642,0.04408926,65.714069,0.23247833,98.397048,408.5209,1.824,1,,,,7.565723E-5,131.9333,7194.6408,1494.7259,0
22097660.92,,5905,85.9973,86.2206,0.325,9.3E-6,85.800446,0.8516084,128467.22,764.5,1653.0648,2.828,5014.0922,5.312,0.051121077,67.25466,0.26782243,98.201078,409.68358,1.98,1,,,,7.5169957E-5,131.42814,7361.7165,1497.2792,0
22098159.09,,5905,86.0024,86.2155,0.325,9.1E-6,85.823013,0.86663632,128443.22,747.5,1653.7934,2.827,5014.1928,3.284,0.21214827,66.302578,0.24241658,98.348495,409.84178,1.818,1,,,,7.6198397E-5,134.50932,7365.5896,1496.6058,0
22098649.89,,5905,85.9988,86.2107,0.325,9.4E-6,85.819673,0.85912522,128390.69,749.9,1653.6862,2.827,5012.7113,3.675,0.058468579,66.145756,0.23905977,98.367671,409.93623,1.849,1,,,,7.634956E-5,132.60516,7365.0163,1496.0519,0
22099428.53,,5905,86.9953,87.2005,0.325,9.3E-6,86.800171,0.86025349,130152.63,771.3,1688.7211,2.752,5093.8431,5.051,0.05295411,67.736908,0.26998346,98.204689,410.89399,1.982,1,,,,7.5817216E-5,132.29151,7534.2697,1499.4513,0
22099930.66,,5905,87.0007,87.1946,0.325,9.4E-6,86.823339,0.876121,129927.25,755.9,1689.4726,2.75,5088.6981,3.28,0.21084528,66.686247,0.24197135,98.366598,411.47814,1.84,1,,,,7.6875542E-5,135.47382,7538.2922,1496.4554,0
22100424.95,,5905,87.004,87.1881,0.325,9.3E-6,86.819568,0.86764978,129971.32,758.3,1689.3523,2.751,5089.7307,3.606,0.064119756,66.615921,0.24264965,98.360067,411.36745,1.866,1,,,,7.6974788E-5,133.37249,7537.6375,1497.0279,0
22101139.23,,5905,87.9981,88.1733,0.325,9.4E-6,87.79638,0.87076222,131600.22,787.6,1724.506,2.656,5167.5007,5.862,0.037733086,68.331246,0.27490215,98.194093,412.5437,2.071,1,,,,7.6244209E-5,133.23184,7708.2044,1498.9254,0
22101646.23,,5905,87.9978,88.1687,0.325,9.4E-6,87.822499,0.8864045,131501.75,763.3,1725.3576,2.654,5165.776,3.038,0.36028325,67.121352,0.24203537,98.381732,412.87423,1.843,1,,,,7.7525303E-5,136.66249,7712.7913,1497.3583,0
22102145.41,,5905,87.996,88.1664,0.325,9.3E-6,87.816428,0.87686807,131437.61,764.3,1725.1765,2.654,5163.9168,3.263,0.11421406,67.03461,0.24712415,98.345845,412.98109,1.861,1,,,,7.76103E-5,134.2427,7711.7251,1496.7314,0
22102860.61,,5905,89.0037,89.1475,0.325,9.3E-6,88.797012,0.87939061,133144.59,795.3,1760.7291,2.544,5244.1284,5.792,0.047905469,68.78959,0.2870584,98.13274,413.96644,2.089,1,,,,7.6877067E-5,134.06922,7884.9093,1499.4265,0
22103370.81,,5905,89.002,89.1429,0.325,9.4E-6,88.821366,0.89644168,132970.18,773,1761.5061,2.541,5240.3423,3.261,0.11999977,67.681944,0.25125544,98.339513,414.44892,1.884,1,,,,7.8004324E-5,137.57918,7889.235,1497.0517,0
22103873.73,,5905,89.0034,89.1387,0.325,9.3E-6,88.816555,0.88682489,132970.8,773.7,1761.3349,2.542,5240.1874,3.372,0.077176676,67.463861,0.25096836,98.335997,414.42515,1.893,1,,,,7.8255461E-5,135.36389,7888.3805,1497.1398,0
22104599.45,,5905,89.9958,90.113,0.325,9.3E-6,89.795258,0.88788053,134523.41,795.4,1797.0739,2.417,5316.5465,5.028,0.051852896,68.851741,0.2793354,98.190697,415.68482,2.05,1,,,,7.7843396E-5,134.92772,8063.1884,1498.1126,0
22105108.63,,5905,90.0023,90.1115,0.325,9.4E-6,89.815708,0.90218625,134540.3,780.7,1797.7507,2.414,5317.6651,3.068,0.13353042,68.086399,0.25725449,98.3149,415.74368,1.892,1,,,,7.8690493E-5,137.70348,8066.8615,1497.9595,0
22105612.16,,5905,90.0001,90.1051,0.325,9.3E-6,89.813701,0.8961201,134368.95,782,1797.6898,2.415,5313.1214,3.442,0.049996682,67.848524,0.25103555,98.350489,416.09794,1.922,1,,,,7.8885699E-5,136.1728,8066.5008,1496.0852,0
22106341.64,,5905,90.9992,91.0841,0.325,9.1E-6,90.795618,0.89613346,136087.41,799,1833.6413,2.249,5394.0322,4.439,0.061362134,69.182022,0.27977611,98.201618,416.97717,2.026,1,,,,7.8593332E-5,135.69705,8243.8443,1498.8324,0
22106853.06,,5905,91.0016,91.0803,0.325,9.3E-6,90.814525,0.91069301,136121.39,789.1,1834.3032,2.246,5395.5829,2.949,0.21723632,68.607423,0.26395514,98.288995,416.99179,1.906,1,,,,7.9243038E-5,138.36404,8247.2779,1498.8945,0
22107359.7,,5905,90.9996,91.0759,0.325,9.4E-6,90.812397,0.90551946,135970.84,789.1,1834.2084,2.246,5391.5494,3.108,0.091624589,68.257469,0.25439293,98.342998,417.30211,1.918,1,,,,7.9569984E-5,137.21485,8246.8914,1497.2718,0
22108088.61,,5905,91.9963,92.0622,0.325,9.4E-6,91.797127,0.90499501,137753.64,804.9,1870.4869,2.058,5474.4704,3.994,0.089550837,69.687031,0.284654,98.188166,418.01287,2.014,1,,,,7.9188796E-5,136.51494,8426.7126,1500.6312,0
22108604,,5905,92.0029,92.0557,0.325,9.1E-6,91.81539,0.9196037,137725.27,797.7,1871.1131,2.054,5474.3545,2.872,0.10183163,68.867669,0.25983884,98.326456,418.15644,1.923,1,,,,8.0079304E-5,139.37406,8430.0659,1500.0238,0
22109158.88,,5905,91.997,92.0516,0.325,9.1E-6,91.811507,0.91330318,137617.56,797.3,1870.966,2.055,5471.3893,2.9,0.072279603,68.760678,0.25981474,98.324397,418.36822,1.925,1,,,,8.016092E-5,137.73534,8429.3528,1498.914,0
22109901.61,,5905,92.9961,93.0403,0.325,9.3E-6,92.798465,0.91387552,139206.87,809.7,1907.6785,1.871,5549.6822,3.478,0.10206593,69.852758,0.28511269,98.194946,419.4572,1.996,1,,,,8.007986E-5,137.52136,8611.555,1500.0989,0
22110417.66,,5905,92.9926,93.0345,0.325,9.4E-6,92.812738,0.92714716,139234.86,808.3,1908.1741,1.869,5550.9103,3.234,0.049946168,69.348803,0.26297041,98.322793,419.46194,1.976,1,,,,8.0633612E-5,139.70552,8614.2043,1500.1698,0
22110932.52,,5905,92.9949,93.03,0.325,9.4E-6,92.81234,0.92263119,139129.8,807,1908.1601,1.869,5548.1476,3.107,0.067205306,69.161106,0.26517551,98.304587,419.68455,1.966,1,,,,8.0818454E-5,138.69761,8614.1305,1499.0442,0
22111672.61,,5905,94.0036,94.0179,0.325,9.1E-6,93.796036,0.92195562,141007.37,816.2,1945.2839,1.718,5634.3932,2.823,0.29295248,70.322046,0.28689132,98.199664,420.09867,1.967,1,,,,8.0755036E-5,138.32221,8797.6963,1503.3404,0
22112193.78,,5905,93.9996,94.0151,0.325,9.4E-6,93.812299,0.93555345,140829.49,813.1,1945.8283,1.716,5630.2838,2.38,0.49993036,69.613711,0.2661128,98.313645,420.55205,1.931,1,,,,8.1475342E-5,140.64409,8800.7474,1501.1836,0
22112707.55,,5905,93.9937,94.0138,0.325,9.4E-6,93.809444,0.92998868,140715.16,814.4,1945.7418,1.716,5627.2061,2.797,0.11268549,69.494244,0.26088824,98.34425,420.78402,1.964,1,,,,8.1559422E-5,139.22742,8800.2118,1500.0106,0
22113451.02,,5905,94.9992,95.0031,0.325,9.1E-6,94.794291,0.92955655,142486.21,824.2,1983.5126,1.623,5711.3122,2.743,0.28194685,70.530338,0.28590815,98.216225,421.38656,1.984,1,,,,8.1605786E-5,138.98849,8985.9576,1503.1096,0
22113974.44,,5905,95.0003,94.9987,0.325,9.4E-6,94.809066,0.94243099,142404.22,823.2,1984.0518,1.622,5709.7063,2.628,0.16681013,70.052207,0.2775759,98.256761,421.62813,1.975,1,,,,8.2124604E-5,141.06068,8988.7591,1502.0105,0
22114493.81,,5905,95.0005,94.9953,0.325,9.3E-6,94.807431,0.93858802,142330.64,823.2,1983.9858,1.622,5707.7153,2.726,0.09525741,69.888661,0.26775191,98.314647,421.77874,1.983,1,,,,8.2266879E-5,140.10441,8988.449,1501.2604,0
22115677.39,,5905,96.0087,95.9869,0.325,9.3E-6,95.812643,0.96250995,144150.59,844.7,2023.0283,1.581,5794.3722,4.497,0.024631157,70.446911,0.26476853,98.35006,422.32424,2.154,1,,,,8.2838381E-5,143.74041,9180.0626,1504.5049,0
22116196.48,,5905,95.9909,95.9899,0.325,9.4E-6,95.804304,0.94844215,144569.98,837.4,2022.7877,1.581,5805.104,3.014,0.18183574,71.239008,0.29464074,98.183026,421.38728,2.032,1,,,,8.2130573E-5,140.89382,9178.4646,1509.0135,0
22116720.48,,5905,96.0066,95.9874,0.325,9.3E-6,95.807538,0.9534808,144305.44,835.2,2022.8732,1.581,5798.2686,2.885,0.085925075,70.700367,0.28417505,98.235124,421.96912,2.021,1,,,,8.2639072E-5,142.47802,9179.0843,1506.2014,0
22117473.81,,5905,97.0057,96.9792,0.325,9.4E-6,96.790209,0.94858483,146306.86,846.1,2061.5833,1.575,5889.3407,2.775,0.48300494,71.653005,0.29880477,98.172056,421.97719,2.038,1,,,,8.2841735E-5,141.40073,9368.3446,1511.5874,0
22118003.16,,5905,96.9973,96.9818,0.325,9.3E-6,96.8065,0.96284475,145220.05,837.3,2062.1573,1.575,5861.481,2.186,1.2325626,70.590605,0.26920567,98.331943,424.38918,1.987,1,,,,8.362894E-5,143.30601,9371.4985,1500.1064,0
22118523.34,,5905,97.0015,96.9729,0.325,9.3E-6,96.797415,0.95431745,145296.56,842.7,2061.8362,1.575,5863.1617,3.23,0.069261059,70.748471,0.28331011,98.248315,424.18415,2.073,1,,,,8.3496938E-5,141.18121,9369.7396,1501.0376,0
22119285.31,,5905,98.0033,97.9768,0.325,9.4E-6,97.787916,0.95517401,146945.78,848,2101.3395,1.588,5945.8128,2.387,0.35009014,71.412064,0.2919921,98.215695,424.94251,2.028,1,,,,8.3895619E-5,141.49694,9562.4766,1502.6988,0
22119811.91,,5905,97.9928,97.9824,0.325,9.3E-6,97.797241,0.9645166,147454.24,853.7,2101.6844,1.588,5959.4602,3.003,0.050728026,71.259824,0.28606036,98.246372,423.88424,2.081,1,,,,8.4258079E-5,142.82413,9564.3004,1507.7546,0
22120335.97,,5905,97.9992,97.9745,0.325,9.4E-6,97.796169,0.96680518,146839.63,854.6,2101.686,1.588,5943.382,3.76,0.027664242,71.397585,0.28507558,98.257965,425.20811,2.142,1,,,,8.386257E-5,142.51965,9564.0907,1501.4865,0
22121094,,5905,98.9992,98.9872,0.325,9.3E-6,98.784391,0.96706032,148588.17,856.9,2141.5934,1.606,6029.0357,2.261,1.2468119,72.124061,0.29955905,98.191891,425.69725,2.043,1,,,,8.4235214E-5,142.79517,9758.3558,1504.1665,0
22121624.59,,5905,98.9969,98.9819,0.325,9.1E-6,98.798016,0.97651964,148619.33,863.9,2142.1151,1.606,6030.3725,3.625,0.044099574,71.486101,0.28509469,98.263663,425.68839,2.157,1,,,,8.4979478E-5,144.24812,9761.048,1504.2744,0
22122152.59,,5905,98.9989,98.9722,0.325,9.4E-6,98.795034,0.97262766,147953.21,856.2,2141.9892,1.606,6012.8192,2.928,0.12970656,71.172098,0.2846012,98.261334,427.1223,2.097,1,,,,8.5104839E-5,142.9722,9760.4588,1497.5774,0
22122903.08,,5905,100.003,99.9859,0.325,9.4E-6,99.781763,0.97004653,150031.11,873.1,2182.5102,1.617,6107.7033,3.822,0.30772958,72.536813,0.32559681,98.051741,426.84502,2.198,1,,,,8.4895569E-5,142.3442,9956.4002,1503.5925,0
22123440.2,,5905,100.006,99.9772,0.325,9.1E-6,99.795422,0.98774465,150182.98,868.3,2183.0348,1.617,6112.2014,2.814,0.097537011,72.343329,0.29739665,98.214847,426.57304,2.115,1,,,,8.5126048E-5,145.07363,9959.1262,1504.9085,0
22123975.39,,5905,99.9975,99.9785,0.325,9.3E-6,99.793024,0.98512973,150324.31,871.8,2182.9692,1.617,6115.8333,3.338,0.14785991,72.411126,0.31431455,98.11482,426.25553,2.159,1,,,,8.5133887E-5,144.68666,9958.6476,1506.3609,0