File: H20250604(P250415 HPHT 475C 6GPa 3.5h YBCO7).dat
[Header]
TITLE,H20250604(P250415 HPHT 475C 6GPa 3.5h YBCO7).dat
BYAPP,HeatCapacity,3.9.11,1.7
INFO,8.45,MASS:Sample Mass (mg)
INFO,0.05,MASSERR:Sample Mass Error (mg)
INFO,666.22,MOLWGHT:Formula Weight (g/mole)
INFO,13,ATOMS:Atoms per Formula Unit
INFO,PPMS Heat Capacity Option 3.9.11 Build 2,APPNAME
DATATYPE,TIME,1
DATATYPE,COMMENT,2
STARTUPAXIS, X, 8, LINEAR, AUTO
STARTUPAXIS, Y1, 10, LINEAR, AUTO
[Data]
Time Stamp (Seconds),Comment (),System Status (Code),Puck Temp (Kelvin),System Temp (Kelvin),Field (Oersted),Pressure (Torr),Sample Temp (Kelvin),Temp Rise (Kelvin),Samp HC (mJ/mole-K),Samp HC Err (mJ/mole-K),Addenda HC (µJ/K),Addenda HC Err (µJ/K),Total HC (µJ/K),Total HC Err (µJ/K),Fit Deviation (ChiSquare),Time Const tau1 (seconds),Time Const tau2 (seconds),Sample Coupling (Percent),Debye Temp (Kelvin),Debye Temp Err (Kelvin),Cal Correction (Factor),Therm Resist (Ohms),Htr Resist (Ohms),Puck Resist (Ohms),Wire Cond (W/K),Meas Time (seconds),Temp Squared (K^2),Samp HC/Temp (mJ/mole-K/K),Addenda Offset HC (µJ/K)
20726073.66,CALFILE: C:\QdPpms\HEATCA~1\TempCal\Standard\Puck1218.cal|Addenda #28 measured on 6/3/2025 from 1.976 to 298.86 K
20726073.81,,5905,2.00152,1.9738,-0.696,9.4E-6,1.9923649,0.022030246,34.165258,0.2407,0.19406856,0.001488,0.62740355,0.001657,0.58867607,0.37556407,0.0021662483,97.302624,180.17827,0.5846,1,,,,1.6927851E-6,0.74644968,3.969518,17.148092,0
20726123.53,,5905,2.00119,1.9732,-0.696,9.3E-6,1.992341,0.021946887,34.218162,0.2397,0.19403906,0.001488,0.62804504,0.001628,0.3457877,0.36989428,0.0019875355,97.485421,180.08321,0.58,1,,,,1.7189331E-6,0.74906904,3.9694226,17.174852,0
20726444.88,,5905,2.16983,2.1454,-0.696,9.4E-6,2.15619,0.022705072,35.852157,0.2433,0.24138103,0.001356,0.69611179,0.001512,0.6785069,0.36998441,0.0022082965,97.374473,191.8862,0.591,1,,,,1.903242E-6,0.72514669,4.6491555,16.62755,0
20726775.81,,5905,2.35012,2.3251,-0.696,9.1E-6,2.3316772,0.022198558,41.961804,0.3312,0.29769143,0.001431,0.82991389,0.002781,3.0221631,0.37368709,0.0017414579,97.981087,196.89995,0.7302,1,,,,2.2397881E-6,0.72393629,5.4367188,17.996403,0
20726824.8,,5905,2.34855,2.3236,-0.696,9.4E-6,2.3302405,0.02318657,41.758398,0.3273,0.29728143,0.00143,0.82692399,0.002723,8.0907036,0.38572497,0.0045535674,94.914886,197.09761,0.7255,1,,,,2.1915114E-6,0.77354761,5.4300209,17.920209,0
20727142.13,,5905,2.54282,2.5201,-0.696,9.3E-6,2.521889,0.024718614,47.601603,0.3762,0.36683098,0.001694,0.97058581,0.003164,16.726188,0.41166952,0.0026189001,97.30989,204.19602,0.7583,1,,,,2.3830656E-6,0.82165205,6.3599241,18.875376,0
20727468.59,,5905,2.7526,2.7338,-0.696,9.3E-6,2.7255557,0.026073763,52.610381,0.3843,0.45358061,0.00197,1.1208643,0.002858,6.4089216,0.43558738,0.0024580665,97.673093,213.44842,0.7251,1,,,,2.5950761E-6,0.83782598,7.4286539,19.302625,0
20727517.75,,5905,2.75152,2.7326,-0.696,9.3E-6,2.7243167,0.026760633,52.594807,0.389,0.45310987,0.001969,1.120196,0.00296,9.7916478,0.44686945,0.005723262,94.75942,213.37245,0.7357,1,,,,2.556578E-6,0.87245832,7.4219016,19.305687,0
20727852.7,,5905,2.97886,2.9621,-0.696,9.4E-6,2.9461005,0.029205219,56.967526,0.4183,0.56397928,0.002364,1.2865268,0.003141,5.2013777,0.45830376,0.0019279481,98.301945,224.68126,0.7681,1,,,,2.8225086E-6,0.93289143,8.6795081,19.336586,0
20728191.59,,5905,3.22507,3.2109,-0.696,9.4E-6,3.1856364,0.030254559,60.772538,0.4502,0.70472888,0.002893,1.4755372,0.003436,1.5439489,0.4772681,0.0017231033,98.562344,237.76915,0.8214,1,,,,3.1039828E-6,0.91754549,10.148279,19.077048,0
20728242.53,,5905,3.2243,3.2101,-0.696,9.4E-6,3.1850961,0.031494361,60.848883,0.4529,0.70456658,0.002892,1.4763433,0.003486,3.8541082,0.49217676,0.0062943463,94.987484,237.62936,0.8256,1,,,,3.0434465E-6,0.9814374,10.144837,19.104254,0
20728587.84,,5905,3.4902,3.4767,-0.696,9.4E-6,3.4447072,0.032889927,65.826898,0.5793,0.88536381,0.003516,1.7202791,0.004149,1.714068,0.50392764,,,250.34927,1.035,1,,,,3.4137424E-6,1.0167348,11.866008,19.109577,0
20728944.47,,5905,3.7773,3.7682,-0.696,9.3E-6,3.7274254,0.035145936,70.963966,0.5207,1.110844,0.003683,2.0109153,0.003905,1.6221778,0.55070542,0.0062417698,95.53725,264.19511,0.9019,1,,,,3.6860938E-6,1.0365286,13.8937,19.038333,0
20728995.73,,5905,3.77665,3.7675,-0.696,9.4E-6,3.7275538,0.036442682,70.664189,0.5196,1.1110623,0.003682,2.0073314,0.003912,2.2622825,0.5507352,0.0065102477,95.349076,264.57729,0.906,1,,,,3.6806931E-6,1.1002122,13.894657,18.957255,0
20729357.94,,5905,4.08899,4.0794,-0.696,9.3E-6,4.0350083,0.039437526,76.923507,0.5374,1.3904643,0.003282,2.3661234,0.003624,3.1453493,0.59041509,0.0069171224,95.313415,278.41169,0.8933,1,,,,4.0414644E-6,1.1817201,16.281292,19.064027,0
20729887.14,,5905,4.42345,4.4301,-0.696,9.3E-6,4.3687929,0.04071809,82.240439,0.6892,1.7635881,0.005731,2.8066845,0.00619,0.49647859,0.64150772,0.0082642999,94.693892,294.80047,1.162,1,,,,4.4094446E-6,1.1826578,19.086351,18.824522,0
20729938.86,,5905,4.42332,4.4331,-0.696,9.4E-6,4.3698965,0.042590573,82.778276,0.6887,1.7653073,0.005745,2.8152254,0.00614,1.2325772,0.65356706,0.0081906607,94.839396,294.23493,1.152,1,,,,4.3404945E-6,1.2628002,19.095995,18.942846,0
20730183.48,,5905,4.78314,4.8023,-0.696,9.4E-6,4.7244717,0.046624649,91.292778,0.878,2.2132304,0.008499,3.3711422,0.008779,1.35503,0.68345934,0.0071185177,95.538013,307.89528,1.381,1,,,,4.9599347E-6,1.4239981,22.320633,19.323383,0
20730427.41,,5905,5.1789,5.2017,-0.696,9.4E-6,5.1162101,0.048386704,104.36607,1.094,2.7535907,0.009951,4.0773175,0.01145,0.15529588,0.73928709,0.0067193439,95.985545,318.87748,1.542,1,,,,5.5397383E-6,1.4821263,26.175606,20.399098,0
20730481.88,,5905,5.18234,5.2085,-0.696,9.3E-6,5.1199509,0.051178125,107.48479,1.19,2.7552064,0.009956,4.1184894,0.01276,0.088590364,0.78798432,0.01107561,93.951038,315.99392,1.602,1,,,,5.2640148E-6,1.5853299,26.213897,20.993324,0
20730728.25,,5905,5.60744,5.6404,-0.696,9.4E-6,5.536787,0.053217292,121.60806,1.876,3.4318874,0.01306,4.9743031,0.02197,0.026985932,0.84415643,0.014949215,92.238202,327.94345,2.187,1,,,,5.9411745E-6,1.6589651,30.656011,21.963652,0
20731013.56,,5905,6.07714,6.0852,-0.696,9.4E-6,5.9890387,0.059184544,140.42063,1.599,4.264734,0.01701,6.0457588,0.01733,1.5684729,0.9258563,0.011388308,94.356109,338.12356,1.756,1,,,,6.5642313E-6,1.9135252,35.868585,23.446272,0
20731070.88,,5905,6.07718,6.0856,-0.696,9.3E-6,5.9887561,0.058332177,139.3989,1.595,4.2639379,0.01701,6.0320036,0.01731,2.1211678,0.92383937,0.009829755,95.073706,338.93165,1.767,1,,,,6.5586584E-6,1.8528456,35.8652,23.276771,0
20731327.17,,5905,6.5791,6.5877,-0.696,9.4E-6,6.4827739,0.062972648,167.07966,1.969,5.2761349,0.02111,7.3952894,0.0216,0.98120077,1.0207828,0.011788405,94.605219,345.39411,1.846,1,,,,7.2790449E-6,2.049642,42.026358,25.772865,0
20731584.48,,5905,7.12104,7.1333,-0.696,9.3E-6,7.0162323,0.064220686,200.58641,2.67,6.5201696,0.03014,9.0643069,0.03034,2.4833797,1.135212,0.015379601,93.647743,351.72093,2.079,1,,,,8.0279393E-6,2.0475819,49.227516,28.588906,0
20731642.45,,5905,7.12202,7.1335,-0.696,9.4E-6,7.0189871,0.068081252,199.88328,2.675,6.5279485,0.03021,9.0631677,0.03043,1.6114573,1.1301786,0.014050927,94.133891,352.27113,2.092,1,,,,8.0588325E-6,2.2589247,49.266181,28.477511,0
20731908.08,,5905,7.71024,7.7238,-0.696,9.4E-6,7.5975677,0.073776175,242.38813,3.302,8.0360164,0.0374,11.110346,0.03773,1.5783819,1.2525152,0.016757713,93.67226,357.57411,2.155,1,,,,8.9169336E-6,2.5065979,57.723035,31.903386,0
20732173.78,,5905,8.3477,8.3628,-0.696,9.3E-6,8.2217554,0.07487548,300.08124,3.12,9.8176978,0.03173,13.623778,0.03254,1.6099764,1.3977767,0.018983477,93.616319,360.36846,1.731,1,,,,9.7993392E-6,2.5140087,67.597262,36.49844,0
20732235.59,,5905,8.34794,8.3631,-0.696,9.4E-6,8.225894,0.080048379,298.64875,3.094,9.821958,0.03172,13.609869,0.03222,1.3991382,1.3754143,0.015520434,94.636038,361.12541,1.73,1,,,,9.9390484E-6,2.7742405,67.665333,36.305932,0
20732510.89,,5905,9.038,9.0556,-0.696,9.4E-6,8.9039653,0.086604439,373.25178,3.791,12.005208,0.03833,16.739346,0.03908,1.5182995,1.5449857,0.019953773,93.954902,362.8925,1.708,1,,,,1.089112E-5,3.0744764,79.280598,41.919725,0
20732786.66,,5905,9.78364,9.8032,-0.696,9.4E-6,9.6353039,0.088327558,464.7837,5.136,14.614728,0.05402,20.509812,0.05501,1.3473327,1.7209372,0.022706499,93.88565,365.01457,1.848,1,,,,1.1982799E-5,3.0902362,92.839081,48.237576,0
20732853.97,,5905,9.78489,9.804,-0.696,9.1E-6,9.6402257,0.093517157,465.73609,5.139,14.634737,0.05414,20.541899,0.05502,1.5171444,1.7038318,0.020760398,94.333071,364.95192,1.845,1,,,,1.211693E-5,3.4178458,92.933952,48.311741,0
20733139.56,,5905,10.5929,10.6134,-0.696,9.4E-6,10.435341,0.10239744,590.57162,6.739,17.717062,0.07227,25.207576,0.07308,0.95916999,1.9136843,0.023809179,94.320585,364.98779,1.898,1,,,,1.3243198E-5,3.830193,108.89634,56.59342,0
20733430.95,,5905,11.4683,11.4878,-0.696,9.4E-6,11.295561,0.10424514,757.22449,7.726,21.426737,0.07922,31.030992,0.07983,2.5291064,2.1409385,0.025478348,94.670561,363.65941,1.719,1,,,,1.4573216E-5,3.8190416,127.58969,67.037352,0
20733503.59,,5905,11.4695,11.4886,-0.696,9.3E-6,11.300682,0.11099687,756.6516,7.725,21.453113,0.07921,31.050102,0.07984,3.1126148,2.1350424,0.024378246,94.874127,363.91607,1.721,1,,,,1.4619018E-5,4.2583236,127.7054,66.95628,0
20733804.47,,5905,12.4169,12.4388,-0.696,9.1E-6,12.235917,0.12168921,976.5613,8.8,25.920837,0.08257,38.307051,0.08417,1.0453952,2.4206858,0.027796596,94.960049,361.90836,1.53,1,,,,1.5913712E-5,4.792564,149.71766,79.811043,0
20734113.17,,5905,13.4428,13.4647,-0.696,9.3E-6,13.242181,0.1229419,1264.958,11.28,31.254942,0.1056,47.299034,0.1071,2.141607,2.7169566,0.030453823,95.18393,359.30458,1.504,1,,,,1.7511335E-5,4.7952891,175.35537,95.524895,0
20734193.34,,5905,13.4443,13.4674,-0.696,9.4E-6,13.248664,0.1316922,1265.6662,11.32,31.295415,0.1058,47.34849,0.1077,1.3008696,2.6996114,0.026351041,95.785042,359.41341,1.509,1,,,,1.7628597E-5,5.4015736,175.5271,95.531611,0
20734506.67,,5905,14.5516,14.5814,-0.696,9.4E-6,14.344944,0.14357314,1662.7082,15.07,37.664248,0.1428,58.753204,0.1448,1.3765392,3.0722708,0.029412145,95.963617,355.32193,1.51,1,,,,1.9228348E-5,6.1569075,205.77741,115.90901,0
20734828.03,,5905,15.7538,15.7867,-0.696,9.4E-6,15.52688,0.1433171,2185.028,19.71,45.169128,0.1856,72.882926,0.1887,1.0928773,3.5191412,0.034715771,95.934283,351.1236,1.486,1,,,,2.0838611E-5,6.0865279,241.08399,140.72551,0
20734919.27,,5905,15.7584,15.7888,-0.696,9.4E-6,15.535807,0.15643027,2183.7596,19.71,45.221506,0.1857,72.919216,0.1887,0.71631772,3.4928366,0.030422162,96.396848,351.39349,1.487,1,,,,2.0990371E-5,7.0264929,241.36129,140.563,0
20735254.05,,5905,17.0565,17.0873,-0.696,9.4E-6,16.819999,0.17057422,2866.4754,23.7,54.09175,0.2055,90.448686,0.2099,0.87095398,3.9928253,0.033256401,96.614151,347.45912,1.351,1,,,,2.2782155E-5,8.0112325,282.91238,170.42066,0
20735600.25,,5905,18.4673,18.4984,-0.696,9.3E-6,18.208841,0.17091006,3762.9723,28.89,64.420974,0.2281,112.14863,0.2334,1.2902553,4.5715732,0.036118489,96.832995,343.52741,1.236,1,,,,2.4678214E-5,7.9987591,331.5619,206.65633,0
20735705.45,,5905,18.4709,18.4997,-0.696,9.4E-6,18.218351,0.18576296,3780.4189,29,64.491891,0.2283,112.44083,0.2341,1.6547061,4.5973569,0.036611582,96.80975,343.17718,1.234,1,,,,2.460546E-5,9.1640202,331.90832,207.50609,0
20736084.16,,5905,19.9912,20.0362,-0.696,9.4E-6,19.728338,0.20271044,4929.5242,36.06,76.550655,0.2586,139.07426,0.269,1.1382197,5.2830402,0.040940757,96.925289,340.14528,1.158,1,,,,2.6494773E-5,10.550251,389.20732,249.87022,0
20736546.39,,5905,22.9964,23.0261,-0.696,9.3E-6,22.700132,0.2334006,7722.6712,52.19,102.7215,0.3034,200.67198,0.3197,2.3574955,6.6726672,0.043097284,97.44924,336.90335,1.034,1,,,,3.0262506E-5,13.17039,515.29599,340.2038,0
20736678.31,,5905,22.9987,23.0285,-0.696,9.4E-6,22.70279,0.23458794,7740.169,52.17,102.74775,0.3035,200.92017,0.3169,2.3662653,6.6817482,0.043147635,97.449777,336.68786,1.03,1,,,,3.0259101E-5,13.393882,515.41669,340.9347,0
20737144,,5905,26.2444,26.2902,-0.696,9.4E-6,25.928912,0.2718512,11506.283,77.4,134.45902,0.441,280.39894,0.4668,3.1072031,8.3795333,0.049765762,97.645811,336.636,1.034,1,,,,3.3682216E-5,16.831067,672.3085,443.76265,0
20737653.27,,5905,29.4948,29.5489,-0.696,9.4E-6,29.138837,0.27101162,15851.324,110.8,169.24821,0.6944,370.29845,0.748,0.34061287,10.187878,0.061204972,97.602581,339.37027,1.117,1,,,,3.6611749E-5,16.730358,849.0718,543.99302,0
20737827.58,,5905,29.503,29.5394,-0.696,9.4E-6,29.163122,0.30463438,15877.695,109.9,169.5065,0.696,370.89122,0.7226,3.6923029,10.049443,0.054791993,97.822257,339.46027,1.102,1,,,,3.7150213E-5,20.223932,850.4877,544.44428,0
20738381.98,,5905,32.7523,32.7972,-0.696,9.4E-6,32.404471,0.33922245,20917.552,143.8,207.89557,0.9073,473.2033,0.9294,3.8885244,11.858456,0.062942462,97.862006,342.98116,1.126,1,,,,4.0179807E-5,23.982797,1050.0497,645.51437,0
20738998.38,,5905,36.0008,36.0552,-0.696,9.4E-6,35.614555,0.3387999,26278.644,178.1,248.73039,1.067,582.03551,1.101,1.0322481,13.661307,0.070648568,97.90181,347.80265,1.147,1,,,,4.2905672E-5,23.681454,1268.3965,737.86249,0
20739213.19,,5905,36.0063,36.0463,-0.696,9.4E-6,35.636444,0.37113816,26321.448,178.1,249.00336,1.067,582.85138,1.096,1.3039214,13.615722,0.066777069,98.009267,347.81398,1.144,1,,,,4.3093912E-5,27.364072,1269.9562,738.61038,0
20739934.66,,5905,39.2516,39.3033,-0.696,9.4E-6,38.860575,0.40563046,32028.261,212,292.56186,1.164,698.79225,1.205,0.73923305,15.442316,0.076496418,97.977773,353.23486,1.156,1,,,,4.5568997E-5,30.935163,1510.1443,824.18392,0
20740724.58,,5905,42.5047,42.5375,-0.696,9.4E-6,42.077606,0.40792443,37766.237,246.9,340.08452,1.261,819.0925,1.331,0.25213935,17.025036,0.077383255,98.138868,359.64042,1.188,1,,,,4.8424525E-5,30.828429,1770.525,897.53767,0
20740979.69,,5905,42.5004,42.5405,-0.696,9.3E-6,42.08485,0.4367039,37837.237,247.2,340.18865,1.262,820.09718,1.328,0.21129442,17.164687,0.080399988,98.081835,359.44594,1.186,1,,,,4.809965E-5,34.179504,1771.1346,899.07028,0
20741657.56,,5905,45.7488,45.8036,-0.696,9.3E-6,45.32218,0.47007993,43989.001,283,391.57626,1.36,949.51067,1.41,1.0338754,18.963007,0.088414464,98.087133,365.22386,1.213,1,,,,5.0410482E-5,37.906735,2054.1,970.58442,0
20742407.55,,5905,48.994,49.0616,-0.696,9.3E-6,48.542061,0.47461457,50010.289,319.7,445.80902,1.462,1080.1144,1.536,0.93208062,20.783103,0.10136291,98.000097,371.62809,1.261,1,,,,5.2338364E-5,37.85609,2356.3317,1030.2465,0
20742707.34,,5905,48.9999,49.0489,-0.696,9.4E-6,48.563566,0.50260538,50001.738,321.3,446.13832,1.462,1080.3353,1.588,0.10968195,20.608904,0.09329327,98.143266,371.81857,1.274,1,,,,5.2764127E-5,41.402848,2358.4199,1029.6142,0
20743508.23,,5905,52.2544,52.2961,-0.696,9.3E-6,51.799056,0.53170314,56138.209,359.1,505.36187,1.524,1217.3907,1.73,0.052814872,22.169444,0.096157422,98.223423,378.04953,1.331,1,,,,5.5254258E-5,44.502168,2683.1422,1083.769,0
20744178.97,,5905,55.4982,55.5537,-0.696,9.3E-6,55.019423,0.53823308,62318.443,391.2,569.28107,1.594,1359.6969,1.657,3.0372253,24.054921,0.11325181,98.077465,383.97252,1.346,1,,,,5.69009E-5,44.582673,3027.1369,1132.6626,0
20744540.84,,5905,55.4999,55.5557,-0.696,9.3E-6,55.034768,0.56456554,62406.361,392,569.5787,1.594,1361.1097,1.667,0.60623852,24.029206,0.11184755,98.09885,383.84323,1.347,1,,,,5.7016959E-5,47.924401,3028.8257,1133.9443,0
20745245.14,,5905,58.7517,58.7991,-0.696,9.4E-6,58.273845,0.59783283,68519.023,430.7,639.20134,1.743,1508.2622,1.843,0.31106792,25.624668,0.11848728,98.118224,389.89428,1.421,1,,,,5.9236315E-5,51.53477,3395.841,1175.8109,0
20745933.72,,5905,62.0005,62.0763,-0.696,9.3E-6,61.491655,0.60201225,74795.035,475.9,712.68316,1.85,1661.3458,2.22,0.11428679,27.694137,0.14538376,97.872509,395.12482,1.536,1,,,,6.0416531E-5,51.129859,3781.2236,1216.3445,0
20746340.59,,5905,62.0069,62.0536,-0.696,9.3E-6,61.511719,0.62516358,74693.972,468.7,713.08932,1.85,1660.4702,1.978,0.17768323,27.173578,0.12407126,98.148416,395.50494,1.49,1,,,,6.1483047E-5,54.302811,3783.6916,1214.3047,0
20747062.61,,5905,65.2608,65.3127,-0.696,9.3E-6,64.758866,0.66384191,80810.678,507.3,791.31539,1.921,1816.2775,2.151,0.064235521,28.77455,0.12970336,98.178596,400.99756,1.569,1,,,,6.3495585E-5,58.614583,4193.7108,1247.8705,0
20747823.73,,5905,68.4989,68.5728,-0.696,9.4E-6,67.965837,0.66259877,86752.498,541.8,872.55133,1.968,1972.8765,2.199,0.18555365,30.642094,0.15816412,97.92363,406.30042,1.628,1,,,,6.4811397E-5,57.360682,4619.3549,1276.4133,0
20748302.23,,5905,68.5028,68.5596,-0.696,9.4E-6,67.99056,0.68868451,86730.379,539.2,873.1385,1.968,1973.1831,2.096,0.21556268,30.266838,0.13999123,98.138156,406.50057,1.61,1,,,,6.557911E-5,60.878384,4622.7162,1275.6238,0
20749096.13,,5905,71.7535,71.8078,-0.696,9.4E-6,71.232198,0.72248791,92387.732,572.6,958.1888,2.029,2129.9884,2.159,0.21098825,31.839489,0.15342162,98.067649,412.27446,1.677,1,,,,6.7298593E-5,64.184202,5074.0261,1296.994,0
20749901.61,,5905,75.0007,75.0579,-0.696,9.4E-6,74.46628,0.72694584,97940.774,608.7,1046.4769,2.087,2288.7085,2.363,0.13615679,33.514764,0.17297037,97.937786,417.81749,1.772,1,,,,6.8715377E-5,63.690267,5545.2268,1315.2366,0
20750421.97,,5905,75.0043,75.0581,-0.696,9.4E-6,74.478846,0.75140355,98079.492,606.4,1046.7913,2.087,2290.7824,2.231,0.26754481,33.386581,0.16489287,98.025627,417.5679,1.748,1,,,,6.9023439E-5,66.793785,5547.0985,1316.8772,0
20751261.98,,5905,75.9967,76.0421,-0.696,9.3E-6,75.474447,0.75899359,99816.683,617,1075.0243,2.09,2341.049,2.264,0.19689962,33.819343,0.16664182,98.031856,419.12319,1.773,1,,,,6.9630657E-5,67.41354,5696.3922,1322.5229,0
20752013.2,,5905,76.999,77.0375,-0.696,9.3E-6,76.468606,0.75928454,101406.55,624.4,1103.6995,2.089,2389.8892,2.191,0.81314426,34.232257,0.16769686,98.045025,420.96744,1.778,1,,,,7.0219143E-5,67.611774,5847.4476,1326.12,0
20752543.7,,5905,77.0034,77.0372,-0.696,9.4E-6,76.474732,0.76942294,101607.35,626.6,1103.8803,2.089,2392.617,2.24,0.39754491,34.311722,0.16905934,98.033488,420.54055,1.787,1,,,,7.0139608E-5,68.480789,5848.3846,1328.6395,0
20753304.88,,5905,77.9997,78.032,-0.696,9.3E-6,77.471273,0.7793597,103275.07,636.3,1133.0693,2.083,2442.9585,2.251,0.22443362,34.753317,0.1734265,98.010188,422.1776,1.808,1,,,,7.0706618E-5,69.446914,6001.7981,1333.0757,0
20754072.14,,5905,79.006,79.0146,-0.696,9.4E-6,78.46275,0.77840849,104876.36,643.7,1162.3685,2.072,2492.5676,2.167,1.2757293,35.073591,0.17102532,98.056861,423.89695,1.813,1,,,,7.146985E-5,69.519674,6156.4031,1336.6389,0
20754578.56,,5905,78.9979,79.0199,-0.696,9.3E-6,78.467616,0.78789336,105059.46,655,1162.5458,2.071,2495.0672,2.619,0.037344388,35.109049,0.17162137,98.051857,423.50526,1.893,1,,,,7.1470934E-5,70.331044,6157.1668,1338.8894,0
20755350.89,,5905,80.0001,80.0039,-0.696,9.3E-6,79.453919,0.79584347,106643.92,655.6,1192.0047,2.056,2544.6226,2.255,0.15215061,35.541712,0.17704798,98.016543,425.19355,1.848,1,,,,7.2006813E-5,70.931561,6312.9252,1342.2109,0
20756126.09,,5905,81.0043,80.9923,-0.696,9.3E-6,80.44964,0.7969467,108048.33,662.4,1221.9948,2.035,2592.4256,2.199,0.2992089,35.828713,0.1735146,98.072832,427.30054,1.858,1,,,,7.2755361E-5,71.241368,6472.1446,1343.0555,0
20756644.59,,5905,81.0028,80.9855,-0.696,9.4E-6,80.45118,0.80669441,108226.37,673.3,1222.0491,2.035,2594.7381,2.638,0.035419242,35.96613,0.17799888,98.030727,426.90298,1.937,1,,,,7.2551564E-5,71.947715,6472.3924,1345.2428,0
20757426.84,,5905,81.9996,81.9744,-0.696,9.3E-6,81.438507,0.81261306,109937.87,675.6,1252.12,2.01,2646.5167,2.314,0.11234886,36.443695,0.18465036,97.985465,428.22416,1.899,1,,,,7.3035921E-5,72.24788,6632.2305,1349.9495,0
20758221.22,,5905,83.0104,82.9535,-0.696,9.4E-6,82.440078,0.81611247,111326.96,682.8,1282.9002,1.98,2694.9154,2.28,0.13743644,36.561815,0.17617889,98.084634,430.31156,1.914,1,,,,7.4105539E-5,73.060398,6796.3664,1350.3985,0
20758789.27,,5905,83.0067,82.9519,-0.696,9.4E-6,82.438781,0.82700737,111611.45,683.2,1282.8881,1.98,2698.5117,2.219,0.1863721,36.875648,0.18746644,97.979902,429.65801,1.902,1,,,,7.3596034E-5,73.820305,6796.1525,1353.8707,0
20759584.52,,5905,83.9986,83.9401,-0.696,9.3E-6,83.428037,0.83133431,113364.61,692,1313.7598,1.946,2751.6196,2.154,0.26634032,37.333093,0.18976234,97.981164,430.81211,1.911,1,,,,7.4121377E-5,73.861853,6960.2374,1358.8311,0
20760384.28,,5905,85.0044,84.9171,-0.696,9.4E-6,84.42621,0.83242049,114885.14,710,1345.3038,1.906,2802.4492,2.598,0.047387805,37.277818,0.17261317,98.160405,432.49807,2.012,1,,,,7.5560069E-5,74.547762,7127.785,1360.7757,0
20760959.72,,5905,85.0057,84.9028,-0.696,9.4E-6,84.425223,0.84618881,115138.52,702.3,1345.3178,1.906,2805.6771,2.16,0.16481696,37.646493,0.18806981,98.016386,431.91887,1.933,1,,,,7.4937596E-5,75.646137,7127.6183,1363.7929,0
20761765.13,,5905,86.0048,85.9003,-0.696,9.3E-6,85.411923,0.84805451,116998.36,712,1376.9432,1.858,2860.8917,2.112,0.23854159,38.224919,0.20006091,97.923471,432.73665,1.945,1,,,,7.5272901E-5,75.271474,7295.1965,1369.813,0
20762575.45,,5905,87.0007,86.885,-0.696,9.3E-6,86.411025,0.84990119,118328.87,738,1409.2135,1.803,2910.0375,2.957,0.038108048,37.938509,0.17203804,98.199516,434.77239,2.118,1,,,,7.7079844E-5,76.142855,7466.8652,1369.3724,0
20763165.03,,5905,87.0021,86.8593,-0.696,9.3E-6,86.407321,0.86378031,118504.28,722.7,1409.1471,1.803,2912.1959,2.221,0.091846731,38.387458,0.18999511,98.036202,434.35697,1.987,1,,,,7.6270041E-5,77.152491,7466.2251,1371.4611,0
20763977.84,,5905,88.0026,87.851,-0.696,9.4E-6,87.391405,0.8661469,120042.87,728.5,1441.5359,1.746,2964.0994,2.049,0.145864,38.932275,0.1992051,97.971237,435.80505,1.978,1,,,,7.6552899E-5,76.656996,7637.2576,1373.6233,0
20764801.75,,5905,89.0083,88.8412,-0.696,9.3E-6,88.3835,0.86840519,120808.74,768.3,1474.5241,1.691,3006.8015,3.57,0.025855357,38.49029,0.16704309,98.27768,439.00467,2.273,1,,,,7.8475531E-5,77.43267,7811.643,1366.8699,0
20765396.42,,5905,88.9965,88.8154,-0.696,9.4E-6,88.375221,0.88313806,121006.68,734.8,1474.3349,1.691,3009.1229,2.091,0.075464997,39.152721,0.20411263,97.934352,438.51355,2.007,1,,,,7.7279969E-5,78.420493,7810.1797,1369.2376,0
20766261.13,,5905,90.0074,89.7882,-0.696,9.3E-6,89.363307,0.88736087,121858.33,738.7,1507.8933,1.643,3053.4831,2.037,0.073132889,39.405948,0.20260826,97.963317,441.46555,2.02,1,,,,7.7902771E-5,78.133697,7985.8006,1363.6282,0
20767127.3,,5905,91.0079,90.7852,-0.696,9.4E-6,90.359912,0.88705507,122337.19,776.7,1542.2502,1.6,3093.9137,3.571,0.030998888,38.89882,0.16274344,98.340194,445.2848,2.32,1,,,,7.9876552E-5,78.411641,8164.9138,1353.8878,0
20767731.78,,5905,91.0052,90.7683,-0.696,9.3E-6,90.351597,0.9038339,122694.16,743.4,1542.0769,1.6,3098.2681,2.03,0.085902965,39.694716,0.20718195,97.933406,444.42314,2.041,1,,,,7.8470124E-5,79.66124,8163.4111,1357.9634,0
20768647.11,,5905,92.0094,91.7506,-0.696,9.3E-6,91.343923,0.90837513,123643.43,748.4,1576.958,1.56,3145.1892,2.002,0.082997136,39.996863,0.2107702,97.914048,447.10753,2.058,1,,,,7.9054608E-5,79.416944,8343.7122,1353.6032,0
20769565.92,,5905,93.0049,92.7419,-0.696,9.4E-6,92.340464,0.90681369,124575.75,782.3,1612.4037,1.524,3192.46,3.322,0.025575387,39.690697,0.17987586,98.203542,449.81796,2.322,1,,,,8.0795537E-5,79.53486,8526.7613,1349.0917,0
20770177.66,,5905,93.0024,92.722,-0.696,9.4E-6,92.334296,0.92221862,124862.96,756.4,1612.2703,1.524,3195.9693,2.055,0.090523733,40.291642,0.21068326,97.930116,449.12296,2.09,1,,,,7.9734754E-5,80.717837,8525.6221,1352.2923,0
20771101.38,,5905,94.0116,93.706,-0.696,9.4E-6,93.333317,0.92696399,126138.53,765.4,1648.36,1.49,3248.2378,2.15,0.067017507,40.547416,0.20739933,97.974733,451.01215,2.13,1,,,,8.0513416E-5,80.691783,8711.108,1351.4845,0
20772028.42,,5905,94.9989,94.7026,-0.696,9.3E-6,94.329855,0.92451709,127522.59,809.2,1684.6989,1.46,3302.1314,3.708,0.01940207,40.358669,0.18709738,98.162501,452.5982,2.438,1,,,,8.2188804E-5,80.803347,8898.1216,1351.8794,0
20772649.13,,5905,95.0058,94.6773,-0.696,9.3E-6,94.322331,0.94059504,127547.73,769.2,1684.5156,1.46,3302.267,1.883,0.17329021,40.942181,0.2203479,97.870024,452.50368,2.104,1,,,,8.108041E-5,81.979732,8896.7021,1352.2539,0
20773586.27,,5905,96.0066,95.6606,-0.696,9.4E-6,95.319821,0.94482447,129256.15,784.2,1721.2971,1.432,3360.7172,2.197,0.064927841,41.168069,0.21086872,97.971567,453.30047,2.185,1,,,,8.2038362E-5,82.058861,9085.8682,1356.0259,0
20774565.53,,5905,97.0066,96.6723,-0.696,9.4E-6,96.308098,0.94431874,130881.9,815.8,1758.1712,1.405,3418.2115,3.252,0.019158662,41.25411,0.19958557,98.082713,454.20449,2.402,1,,,,8.3241344E-5,82.233027,9275.2498,1358.9916,0
20775196.39,,5905,97.0027,96.6393,-0.696,9.4E-6,96.303449,0.95782959,130794.64,789.5,1758.0488,1.405,3416.9824,1.981,0.097190839,41.568448,0.22092843,97.895784,454.38533,2.169,1,,,,8.2620047E-5,83.274281,9274.3542,1358.1512,0
20776145.84,,5905,98.0113,97.6289,-0.696,9.3E-6,97.305311,0.96553517,132189.38,805,1795.9525,1.382,3472.5762,2.414,0.050584584,41.768039,0.21065926,98.001598,455.85028,2.272,1,,,,8.3536775E-5,83.737336,9468.3235,1358.5012,0
20777138.95,,5905,99.0074,98.6368,-0.696,9.3E-6,98.297883,0.96533443,133516.31,832.9,1833.9943,1.366,3527.4481,3.345,0.022706225,41.848549,0.20004955,98.104283,457.39014,2.467,1,,,,8.4668019E-5,83.790233,9662.4739,1358.2826,0
20777780.3,,5905,99.0015,98.6122,-0.696,9.4E-6,98.293691,0.97812162,133774.24,808.5,1833.9014,1.366,3530.6267,2.087,0.083057878,42.338533,0.22515717,97.89356,456.7689,2.236,1,,,,8.3807026E-5,84.663186,9661.6498,1360.9647,0
20778739.34,,5905,100.016,99.5969,-0.696,9.3E-6,99.295395,0.98058994,135561.65,824.9,1872.9198,1.357,3592.3158,2.439,0.048319565,42.642434,0.221058,97.945584,457.23602,2.325,1,,,,8.4649665E-5,84.437821,9859.5756,1365.236,0
20779822.72,,5905,100.005,99.6079,-0.696,9.3E-6,99.318754,1.0192964,133960.02,804.6,1873.7563,1.357,3572.8379,1.751,0.82171731,42.245515,0.20684145,98.057598,461.09498,2.197,1,,,,8.4953933E-5,89.083192,9864.2148,1348.7888,0
20781348.81,,5905,106.412,105.97,-0.696,9.4E-6,105.6582,1.0181378,144592.39,906.1,2132.255,1.473,3966.1923,3.783,0.025244517,44.037046,0.21310905,98.074604,464.67586,2.737,1,,,,9.0444791E-5,86.630202,11163.656,1368.4918,0
20782822.63,,5905,112.807,112.394,-0.696,9.4E-6,112.07958,1.0747432,153364.14,983.7,2409.8569,1.578,4355.0507,4.817,0.042022856,45.59271,0.19543973,98.283419,471.359,3.11,1,,,,9.5855034E-5,90.131543,12561.831,1368.3505,0
20784131.52,,5905,119.219,118.819,-0.696,9.3E-6,118.50406,1.1244088,161582.77,1054,2695.337,1.639,4744.7717,5.633,0.050883625,46.858983,0.18246406,98.428615,477.80032,3.46,1,,,,0.00010155917,92.476228,14043.211,1363.521,0
20785463.67,,5905,125.61,125.32,-0.696,9.3E-6,124.91029,1.1953107,171372.75,1066,2991.7427,2.181,5165.3486,4.151,0.03585157,49.347848,0.2453836,97.98624,478.65362,3.378,1,,,,0.00010505505,97.196469,15602.581,1371.9666,0
20786824.06,,5905,132.015,131.786,-0.696,9.3E-6,131.2967,1.2584047,178961.44,1099,3295.1991,2.983,5565.0562,3.728,0.063871941,51.023209,0.28520727,97.720598,483.33944,3.503,1,,,,0.00010949475,100.78456,17238.824,1363.0307,0
20788215.36,,5905,138.406,138.263,-0.696,9.4E-6,137.66941,1.3289864,186378.62,1140,3587.5135,3.502,5951.4463,3.643,1.0385614,52.583769,0.30046832,97.651712,486.9314,3.706,1,,,,0.00011361217,104.65037,18952.867,1353.8128,0
20789629.78,,5905,144.801,144.76,-0.696,9.4E-6,144.07486,1.3954569,192406.09,1192,3874.3398,3.863,6314.722,4.498,0.091549325,53.933496,0.32105945,97.532682,492.95062,4.115,1,,,,0.00011752851,107.28022,20757.565,1335.4591,0
20790345.56,,5905,148.006,148.006,-0.696,9.3E-6,147.23639,1.4220021,196553.11,1211,4016.0843,4.138,6509.0653,4.285,8.5037045,54.981527,0.38949195,97.064184,492.18598,4.196,1,,,,0.00011891543,107.86699,21678.556,1334.9492,0